Workbook

Sheet Parametros
A1: Parámetros de la escala de tallas
A2: Azul = dato de entrada · gris violeta = fórmula. Fuente de las horas: informe de septiembre de 2026 (Viva Aerobus), hoja «Seguimiento Mes».
A3: Parámetro | B3: Valor | C3: Fundamento
A4: Margen de desviación | B4: 0.3 | C4: Regla: tiempo real + 30 %
A5: Horas de trabajo de una característica XL | B5: 30 | C5: Tope por característica
A6: Tope de una característica (h con margen) | B6: =B5*(1+B4) -> 39 | C6: 30 h + 30 % = 39 h
A7: Puntos por persona al mes | B7: =Septiembre!B10/B8 -> 39 | C7: Puntos de septiembre (tareas terminadas) / personas
A8: Personas del equipo de referencia | B8: 3 | C8: Informe de septiembre
A9: Jornada semanal por persona (h) | B9: 42 | C9: Lunes a viernes
A10: Semanas por mes | B10: 4 | C10: 42 x 4
A11: Horas disponibles por persona al mes | B11: =B9*B10 -> 168
A14: Talla | B14: Puntos | C14: Tope (h con margen) | D14: Tope (h de trabajo) | E14: Qué es | F14: Desde (h de trabajo) | G14: Punto medio (h de trabajo)
A15: XS | B15: 1 | C15: 6 | D15: =C15/(1+$B$4) -> 4.6153846 | E15: Ajuste puntual: un cambio menor o una corrección acotada | F15: 0 | G15: =(F15+D15)/2 -> 2.3076923
A16: S | B16: 2 | C16: 11 | D16: =C16/(1+$B$4) -> 8.4615385 | E16: Cambio acotado sobre un componente existente | F16: =D15 -> 4.6153846 | G16: =(F16+D16)/2 -> 6.5384615
A17: M | B17: 3 | C17: 17 | D17: =C17/(1+$B$4) -> 13.076923 | E17: Funcionalidad estándar con sus pruebas | F17: =D16 -> 8.4615385 | G17: =(F17+D17)/2 -> 10.769231
A18: L | B18: 5 | C18: 28 | D18: =C18/(1+$B$4) -> 21.538462 | E18: Funcionalidad con varias reglas o integraciones | F18: =D17 -> 13.076923 | G18: =(F18+D18)/2 -> 17.307692
A19: XL | B19: 8 | C19: =B6 -> 39 | D19: =C19/(1+$B$4) -> 30 | E19: La mayor permitida; lo que la supere se divide | F19: =D18 -> 21.538462 | G19: =(F19+D19)/2 -> 25.769231
A21: Una característica que pasa de XL se divide: bloques XL completos de 39 h (30 h de trabajo) más el resto con la talla que lo cubre.
A22: Punto medio = esfuerzo típico de una característica de esa talla; sirve para comprobar que las mezclas piden un esfuerzo parecido al del plan.

Sheet Tareas
A1: Conversión de horas a tallas, tarea por tarea
A2: Completa = horas totales de la tarea (H + I del informe), es el tamaño de la característica. Septiembre = solo las horas del mes (columna I), es la capacidad que el equipo dedicó.
Q3: Septiembre: cantidad por talla | W3: Completa: cantidad por talla
A4: Tarea | B4: Estado | C4: Integrante | D4: Grupo | E4: Horas completas (H+I) | F4: Horas septiembre (I) | G4: Completa: h con margen | H4: bloques XL | I4: resto (h) | J4: talla del resto | K4: PUNTOS completa | L4: Sept.: h con margen | M4: bloques XL | N4: resto (h) | O4: talla del resto | P4: PUNTOS sept. | Q4: XL | R4: L | S4: M | T4: S | U4: XS | V4: Control sept. | W4: XL | X4: L | Y4: M | Z4: S | AA4: XS | AB4: Control compl.
A5: API-1663 | B5: Ready for prod | C5: 1 | D5: Terminada | E5: 60 | F5: 20 | G5: =ROUND(E5*(1+Parametros!$B$4),6) -> 78 | H5: =INT(G5/Parametros!$B$6) -> 2 | I5: =ROUND(G5-H5*Parametros!$B$6,6) -> 0 | J5: =IF(I5>0,COUNTIF(Parametros!$C$15:$C$19,"<"&I5)+1,0) -> 0 | K5: =H5*Parametros!$B$19+IF(J5>0,INDEX(Parametros!$B$15:$B$19,J5),0) -> 16 | L5: =ROUND(F5*(1+Parametros!$B$4),6) -> 26 | M5: =INT(L5/Parametros!$B$6) -> 0 | N5: =ROUND(L5-M5*Parametros!$B$6,6) -> 26 | O5: =IF(N5>0,COUNTIF(Parametros!$C$15:$C$19,"<"&N5)+1,0) -> 4 | P5: =M5*Parametros!$B$19+IF(O5>0,INDEX(Parametros!$B$15:$B$19,O5),0) -> 5 | Q5: =M5+IF(O5=5,1,0) -> 0 | R5: =IF(O5=4,1,0) -> 1 | S5: =IF(O5=3,1,0) -> 0 | T5: =IF(O5=2,1,0) -> 0 | U5: =IF(O5=1,1,0) -> 0 | V5: =IF(Q5*Parametros!$B$19+R5*Parametros!$B$18+S5*Parametros!$B$17+T5*Parametros!$B$16+U5*Parametros!$B$15=P5,"OK","ERROR") -> OK | W5: =H5+IF(J5=5,1,0) -> 2 | X5: =IF(J5=4,1,0) -> 0 | Y5: =IF(J5=3,1,0) -> 0 | Z5: =IF(J5=2,1,0) -> 0 | AA5: =IF(J5=1,1,0) -> 0 | AB5: =IF(W5*Parametros!$B$19+X5*Parametros!$B$18+Y5*Parametros!$B$17+Z5*Parametros!$B$16+AA5*Parametros!$B$15=K5,"OK","ERROR") -> OK
A6: API-1834 | B6: Finalizada | C6: 1 | D6: Terminada | E6: 57 | F6: 33 | G6: =ROUND(E6*(1+Parametros!$B$4),6) -> 74.1 | H6: =INT(G6/Parametros!$B$6) -> 1 | I6: =ROUND(G6-H6*Parametros!$B$6,6) -> 35.1 | J6: =IF(I6>0,COUNTIF(Parametros!$C$15:$C$19,"<"&I6)+1,0) -> 5 | K6: =H6*Parametros!$B$19+IF(J6>0,INDEX(Parametros!$B$15:$B$19,J6),0) -> 16 | L6: =ROUND(F6*(1+Parametros!$B$4),6) -> 42.9 | M6: =INT(L6/Parametros!$B$6) -> 1 | N6: =ROUND(L6-M6*Parametros!$B$6,6) -> 3.9 | O6: =IF(N6>0,COUNTIF(Parametros!$C$15:$C$19,"<"&N6)+1,0) -> 1 | P6: =M6*Parametros!$B$19+IF(O6>0,INDEX(Parametros!$B$15:$B$19,O6),0) -> 9 | Q6: =M6+IF(O6=5,1,0) -> 1 | R6: =IF(O6=4,1,0) -> 0 | S6: =IF(O6=3,1,0) -> 0 | T6: =IF(O6=2,1,0) -> 0 | U6: =IF(O6=1,1,0) -> 1 | V6: =IF(Q6*Parametros!$B$19+R6*Parametros!$B$18+S6*Parametros!$B$17+T6*Parametros!$B$16+U6*Parametros!$B$15=P6,"OK","ERROR") -> OK | W6: =H6+IF(J6=5,1,0) -> 2 | X6: =IF(J6=4,1,0) -> 0 | Y6: =IF(J6=3,1,0) -> 0 | Z6: =IF(J6=2,1,0) -> 0 | AA6: =IF(J6=1,1,0) -> 0 | AB6: =IF(W6*Parametros!$B$19+X6*Parametros!$B$18+Y6*Parametros!$B$17+Z6*Parametros!$B$16+AA6*Parametros!$B$15=K6,"OK","ERROR") -> OK
A7: API-1738 | B7: Finalizado | C7: 1 | D7: Terminada | E7: 53 | F7: 27 | G7: =ROUND(E7*(1+Parametros!$B$4),6) -> 68.9 | H7: =INT(G7/Parametros!$B$6) -> 1 | I7: =ROUND(G7-H7*Parametros!$B$6,6) -> 29.9 | J7: =IF(I7>0,COUNTIF(Parametros!$C$15:$C$19,"<"&I7)+1,0) -> 5 | K7: =H7*Parametros!$B$19+IF(J7>0,INDEX(Parametros!$B$15:$B$19,J7),0) -> 16 | L7: =ROUND(F7*(1+Parametros!$B$4),6) -> 35.1 | M7: =INT(L7/Parametros!$B$6) -> 0 | N7: =ROUND(L7-M7*Parametros!$B$6,6) -> 35.1 | O7: =IF(N7>0,COUNTIF(Parametros!$C$15:$C$19,"<"&N7)+1,0) -> 5 | P7: =M7*Parametros!$B$19+IF(O7>0,INDEX(Parametros!$B$15:$B$19,O7),0) -> 8 | Q7: =M7+IF(O7=5,1,0) -> 1 | R7: =IF(O7=4,1,0) -> 0 | S7: =IF(O7=3,1,0) -> 0 | T7: =IF(O7=2,1,0) -> 0 | U7: =IF(O7=1,1,0) -> 0 | V7: =IF(Q7*Parametros!$B$19+R7*Parametros!$B$18+S7*Parametros!$B$17+T7*Parametros!$B$16+U7*Parametros!$B$15=P7,"OK","ERROR") -> OK | W7: =H7+IF(J7=5,1,0) -> 2 | X7: =IF(J7=4,1,0) -> 0 | Y7: =IF(J7=3,1,0) -> 0 | Z7: =IF(J7=2,1,0) -> 0 | AA7: =IF(J7=1,1,0) -> 0 | AB7: =IF(W7*Parametros!$B$19+X7*Parametros!$B$18+Y7*Parametros!$B$17+Z7*Parametros!$B$16+AA7*Parametros!$B$15=K7,"OK","ERROR") -> OK
A8: API-1693 | B8: Ready for prod | C8: 2 | D8: Terminada | E8: 45 | F8: 6 | G8: =ROUND(E8*(1+Parametros!$B$4),6) -> 58.5 | H8: =INT(G8/Parametros!$B$6) -> 1 | I8: =ROUND(G8-H8*Parametros!$B$6,6) -> 19.5 | J8: =IF(I8>0,COUNTIF(Parametros!$C$15:$C$19,"<"&I8)+1,0) -> 4 | K8: =H8*Parametros!$B$19+IF(J8>0,INDEX(Parametros!$B$15:$B$19,J8),0) -> 13 | L8: =ROUND(F8*(1+Parametros!$B$4),6) -> 7.8 | M8: =INT(L8/Parametros!$B$6) -> 0 | N8: =ROUND(L8-M8*Parametros!$B$6,6) -> 7.8 | O8: =IF(N8>0,COUNTIF(Parametros!$C$15:$C$19,"<"&N8)+1,0) -> 2 | P8: =M8*Parametros!$B$19+IF(O8>0,INDEX(Parametros!$B$15:$B$19,O8),0) -> 2 | Q8: =M8+IF(O8=5,1,0) -> 0 | R8: =IF(O8=4,1,0) -> 0 | S8: =IF(O8=3,1,0) -> 0 | T8: =IF(O8=2,1,0) -> 1 | U8: =IF(O8=1,1,0) -> 0 | V8: =IF(Q8*Parametros!$B$19+R8*Parametros!$B$18+S8*Parametros!$B$17+T8*Parametros!$B$16+U8*Parametros!$B$15=P8,"OK","ERROR") -> OK | W8: =H8+IF(J8=5,1,0) -> 1 | X8: =IF(J8=4,1,0) -> 1 | Y8: =IF(J8=3,1,0) -> 0 | Z8: =IF(J8=2,1,0) -> 0 | AA8: =IF(J8=1,1,0) -> 0 | AB8: =IF(W8*Parametros!$B$19+X8*Parametros!$B$18+Y8*Parametros!$B$17+Z8*Parametros!$B$16+AA8*Parametros!$B$15=K8,"OK","ERROR") -> OK
A9: API-1427 | B9: Finalizada | C9: 2 | D9: Terminada | E9: 43 | F9: 2 | G9: =ROUND(E9*(1+Parametros!$B$4),6) -> 55.9 | H9: =INT(G9/Parametros!$B$6) -> 1 | I9: =ROUND(G9-H9*Parametros!$B$6,6) -> 16.9 | J9: =IF(I9>0,COUNTIF(Parametros!$C$15:$C$19,"<"&I9)+1,0) -> 3 | K9: =H9*Parametros!$B$19+IF(J9>0,INDEX(Parametros!$B$15:$B$19,J9),0) -> 11 | L9: =ROUND(F9*(1+Parametros!$B$4),6) -> 2.6 | M9: =INT(L9/Parametros!$B$6) -> 0 | N9: =ROUND(L9-M9*Parametros!$B$6,6) -> 2.6 | O9: =IF(N9>0,COUNTIF(Parametros!$C$15:$C$19,"<"&N9)+1,0) -> 1 | P9: =M9*Parametros!$B$19+IF(O9>0,INDEX(Parametros!$B$15:$B$19,O9),0) -> 1 | Q9: =M9+IF(O9=5,1,0) -> 0 | R9: =IF(O9=4,1,0) -> 0 | S9: =IF(O9=3,1,0) -> 0 | T9: =IF(O9=2,1,0) -> 0 | U9: =IF(O9=1,1,0) -> 1 | V9: =IF(Q9*Parametros!$B$19+R9*Parametros!$B$18+S9*Parametros!$B$17+T9*Parametros!$B$16+U9*Parametros!$B$15=P9,"OK","ERROR") -> OK | W9: =H9+IF(J9=5,1,0) -> 1 | X9: =IF(J9=4,1,0) -> 0 | Y9: =IF(J9=3,1,0) -> 1 | Z9: =IF(J9=2,1,0) -> 0 | AA9: =IF(J9=1,1,0) -> 0 | AB9: =IF(W9*Parametros!$B$19+X9*Parametros!$B$18+Y9*Parametros!$B$17+Z9*Parametros!$B$16+AA9*Parametros!$B$15=K9,"OK","ERROR") -> OK
A10: API-1832 | B10: Ready for prod | C10: 1 | D10: Terminada | E10: 40 | F10: 40 | G10: =ROUND(E10*(1+Parametros!$B$4),6) -> 52 | H10: =INT(G10/Parametros!$B$6) -> 1 | I10: =ROUND(G10-H10*Parametros!$B$6,6) -> 13 | J10: =IF(I10>0,COUNTIF(Parametros!$C$15:$C$19,"<"&I10)+1,0) -> 3 | K10: =H10*Parametros!$B$19+IF(J10>0,INDEX(Parametros!$B$15:$B$19,J10),0) -> 11 | L10: =ROUND(F10*(1+Parametros!$B$4),6) -> 52 | M10: =INT(L10/Parametros!$B$6) -> 1 | N10: =ROUND(L10-M10*Parametros!$B$6,6) -> 13 | O10: =IF(N10>0,COUNTIF(Parametros!$C$15:$C$19,"<"&N10)+1,0) -> 3 | P10: =M10*Parametros!$B$19+IF(O10>0,INDEX(Parametros!$B$15:$B$19,O10),0) -> 11 | Q10: =M10+IF(O10=5,1,0) -> 1 | R10: =IF(O10=4,1,0) -> 0 | S10: =IF(O10=3,1,0) -> 1 | T10: =IF(O10=2,1,0) -> 0 | U10: =IF(O10=1,1,0) -> 0 | V10: =IF(Q10*Parametros!$B$19+R10*Parametros!$B$18+S10*Parametros!$B$17+T10*Parametros!$B$16+U10*Parametros!$B$15=P10,"OK","ERROR") -> OK | W10: =H10+IF(J10=5,1,0) -> 1 | X10: =IF(J10=4,1,0) -> 0 | Y10: =IF(J10=3,1,0) -> 1 | Z10: =IF(J10=2,1,0) -> 0 | AA10: =IF(J10=1,1,0) -> 0 | AB10: =IF(W10*Parametros!$B$19+X10*Parametros!$B$18+Y10*Parametros!$B$17+Z10*Parametros!$B$16+AA10*Parametros!$B$15=K10,"OK","ERROR") -> OK
A11: API-1877 | B11: Finalizada | C11: 3 | D11: Terminada | E11: 36 | F11: 36 | G11: =ROUND(E11*(1+Parametros!$B$4),6) -> 46.8 | H11: =INT(G11/Parametros!$B$6) -> 1 | I11: =ROUND(G11-H11*Parametros!$B$6,6) -> 7.8 | J11: =IF(I11>0,COUNTIF(Parametros!$C$15:$C$19,"<"&I11)+1,0) -> 2 | K11: =H11*Parametros!$B$19+IF(J11>0,INDEX(Parametros!$B$15:$B$19,J11),0) -> 10 | L11: =ROUND(F11*(1+Parametros!$B$4),6) -> 46.8 | M11: =INT(L11/Parametros!$B$6) -> 1 | N11: =ROUND(L11-M11*Parametros!$B$6,6) -> 7.8 | O11: =IF(N11>0,COUNTIF(Parametros!$C$15:$C$19,"<"&N11)+1,0) -> 2 | P11: =M11*Parametros!$B$19+IF(O11>0,INDEX(Parametros!$B$15:$B$19,O11),0) -> 10 | Q11: =M11+IF(O11=5,1,0) -> 1 | R11: =IF(O11=4,1,0) -> 0 | S11: =IF(O11=3,1,0) -> 0 | T11: =IF(O11=2,1,0) -> 1 | U11: =IF(O11=1,1,0) -> 0 | V11: =IF(Q11*Parametros!$B$19+R11*Parametros!$B$18+S11*Parametros!$B$17+T11*Parametros!$B$16+U11*Parametros!$B$15=P11,"OK","ERROR") -> OK | W11: =H11+IF(J11=5,1,0) -> 1 | X11: =IF(J11=4,1,0) -> 0 | Y11: =IF(J11=3,1,0) -> 0 | Z11: =IF(J11=2,1,0) -> 1 | AA11: =IF(J11=1,1,0) -> 0 | AB11: =IF(W11*Parametros!$B$19+X11*Parametros!$B$18+Y11*Parametros!$B$17+Z11*Parametros!$B$16+AA11*Parametros!$B$15=K11,"OK","ERROR") -> OK
A12: API-1839 | B12: Finalizado | C12: 3 | D12: Terminada | E12: 32 | F12: 32 | G12: =ROUND(E12*(1+Parametros!$B$4),6) -> 41.6 | H12: =INT(G12/Parametros!$B$6) -> 1 | I12: =ROUND(G12-H12*Parametros!$B$6,6) -> 2.6 | J12: =IF(I12>0,COUNTIF(Parametros!$C$15:$C$19,"<"&I12)+1,0) -> 1 | K12: =H12*Parametros!$B$19+IF(J12>0,INDEX(Parametros!$B$15:$B$19,J12),0) -> 9 | L12: =ROUND(F12*(1+Parametros!$B$4),6) -> 41.6 | M12: =INT(L12/Parametros!$B$6) -> 1 | N12: =ROUND(L12-M12*Parametros!$B$6,6) -> 2.6 | O12: =IF(N12>0,COUNTIF(Parametros!$C$15:$C$19,"<"&N12)+1,0) -> 1 | P12: =M12*Parametros!$B$19+IF(O12>0,INDEX(Parametros!$B$15:$B$19,O12),0) -> 9 | Q12: =M12+IF(O12=5,1,0) -> 1 | R12: =IF(O12=4,1,0) -> 0 | S12: =IF(O12=3,1,0) -> 0 | T12: =IF(O12=2,1,0) -> 0 | U12: =IF(O12=1,1,0) -> 1 | V12: =IF(Q12*Parametros!$B$19+R12*Parametros!$B$18+S12*Parametros!$B$17+T12*Parametros!$B$16+U12*Parametros!$B$15=P12,"OK","ERROR") -> OK | W12: =H12+IF(J12=5,1,0) -> 1 | X12: =IF(J12=4,1,0) -> 0 | Y12: =IF(J12=3,1,0) -> 0 | Z12: =IF(J12=2,1,0) -> 0 | AA12: =IF(J12=1,1,0) -> 1 | AB12: =IF(W12*Parametros!$B$19+X12*Parametros!$B$18+Y12*Parametros!$B$17+Z12*Parametros!$B$16+AA12*Parametros!$B$15=K12,"OK","ERROR") -> OK
A13: API-1867 | B13: Finalizada | C13: 2 | D13: Terminada | E13: 31 | F13: 31 | G13: =ROUND(E13*(1+Parametros!$B$4),6) -> 40.3 | H13: =INT(G13/Parametros!$B$6) -> 1 | I13: =ROUND(G13-H13*Parametros!$B$6,6) -> 1.3 | J13: =IF(I13>0,COUNTIF(Parametros!$C$15:$C$19,"<"&I13)+1,0) -> 1 | K13: =H13*Parametros!$B$19+IF(J13>0,INDEX(Parametros!$B$15:$B$19,J13),0) -> 9 | L13: =ROUND(F13*(1+Parametros!$B$4),6) -> 40.3 | M13: =INT(L13/Parametros!$B$6) -> 1 | N13: =ROUND(L13-M13*Parametros!$B$6,6) -> 1.3 | O13: =IF(N13>0,COUNTIF(Parametros!$C$15:$C$19,"<"&N13)+1,0) -> 1 | P13: =M13*Parametros!$B$19+IF(O13>0,INDEX(Parametros!$B$15:$B$19,O13),0) -> 9 | Q13: =M13+IF(O13=5,1,0) -> 1 | R13: =IF(O13=4,1,0) -> 0 | S13: =IF(O13=3,1,0) -> 0 | T13: =IF(O13=2,1,0) -> 0 | U13: =IF(O13=1,1,0) -> 1 | V13: =IF(Q13*Parametros!$B$19+R13*Parametros!$B$18+S13*Parametros!$B$17+T13*Parametros!$B$16+U13*Parametros!$B$15=P13,"OK","ERROR") -> OK | W13: =H13+IF(J13=5,1,0) -> 1 | X13: =IF(J13=4,1,0) -> 0 | Y13: =IF(J13=3,1,0) -> 0 | Z13: =IF(J13=2,1,0) -> 0 | AA13: =IF(J13=1,1,0) -> 1 | AB13: =IF(W13*Parametros!$B$19+X13*Parametros!$B$18+Y13*Parametros!$B$17+Z13*Parametros!$B$16+AA13*Parametros!$B$15=K13,"OK","ERROR") -> OK
A14: API-1901 | B14: Ready for prod | C14: 2 | D14: Terminada | E14: 25 | F14: 25 | G14: =ROUND(E14*(1+Parametros!$B$4),6) -> 32.5 | H14: =INT(G14/Parametros!$B$6) -> 0 | I14: =ROUND(G14-H14*Parametros!$B$6,6) -> 32.5 | J14: =IF(I14>0,COUNTIF(Parametros!$C$15:$C$19,"<"&I14)+1,0) -> 5 | K14: =H14*Parametros!$B$19+IF(J14>0,INDEX(Parametros!$B$15:$B$19,J14),0) -> 8 | L14: =ROUND(F14*(1+Parametros!$B$4),6) -> 32.5 | M14: =INT(L14/Parametros!$B$6) -> 0 | N14: =ROUND(L14-M14*Parametros!$B$6,6) -> 32.5 | O14: =IF(N14>0,COUNTIF(Parametros!$C$15:$C$19,"<"&N14)+1,0) -> 5 | P14: =M14*Parametros!$B$19+IF(O14>0,INDEX(Parametros!$B$15:$B$19,O14),0) -> 8 | Q14: =M14+IF(O14=5,1,0) -> 1 | R14: =IF(O14=4,1,0) -> 0 | S14: =IF(O14=3,1,0) -> 0 | T14: =IF(O14=2,1,0) -> 0 | U14: =IF(O14=1,1,0) -> 0 | V14: =IF(Q14*Parametros!$B$19+R14*Parametros!$B$18+S14*Parametros!$B$17+T14*Parametros!$B$16+U14*Parametros!$B$15=P14,"OK","ERROR") -> OK | W14: =H14+IF(J14=5,1,0) -> 1 | X14: =IF(J14=4,1,0) -> 0 | Y14: =IF(J14=3,1,0) -> 0 | Z14: =IF(J14=2,1,0) -> 0 | AA14: =IF(J14=1,1,0) -> 0 | AB14: =IF(W14*Parametros!$B$19+X14*Parametros!$B$18+Y14*Parametros!$B$17+Z14*Parametros!$B$16+AA14*Parametros!$B$15=K14,"OK","ERROR") -> OK
A15: API-1764 | B15: Ready for prod | C15: 1 | D15: Terminada | E15: 24 | F15: 24 | G15: =ROUND(E15*(1+Parametros!$B$4),6) -> 31.2 | H15: =INT(G15/Parametros!$B$6) -> 0 | I15: =ROUND(G15-H15*Parametros!$B$6,6) -> 31.2 | J15: =IF(I15>0,COUNTIF(Parametros!$C$15:$C$19,"<"&I15)+1,0) -> 5 | K15: =H15*Parametros!$B$19+IF(J15>0,INDEX(Parametros!$B$15:$B$19,J15),0) -> 8 | L15: =ROUND(F15*(1+Parametros!$B$4),6) -> 31.2 | M15: =INT(L15/Parametros!$B$6) -> 0 | N15: =ROUND(L15-M15*Parametros!$B$6,6) -> 31.2 | O15: =IF(N15>0,COUNTIF(Parametros!$C$15:$C$19,"<"&N15)+1,0) -> 5 | P15: =M15*Parametros!$B$19+IF(O15>0,INDEX(Parametros!$B$15:$B$19,O15),0) -> 8 | Q15: =M15+IF(O15=5,1,0) -> 1 | R15: =IF(O15=4,1,0) -> 0 | S15: =IF(O15=3,1,0) -> 0 | T15: =IF(O15=2,1,0) -> 0 | U15: =IF(O15=1,1,0) -> 0 | V15: =IF(Q15*Parametros!$B$19+R15*Parametros!$B$18+S15*Parametros!$B$17+T15*Parametros!$B$16+U15*Parametros!$B$15=P15,"OK","ERROR") -> OK | W15: =H15+IF(J15=5,1,0) -> 1 | X15: =IF(J15=4,1,0) -> 0 | Y15: =IF(J15=3,1,0) -> 0 | Z15: =IF(J15=2,1,0) -> 0 | AA15: =IF(J15=1,1,0) -> 0 | AB15: =IF(W15*Parametros!$B$19+X15*Parametros!$B$18+Y15*Parametros!$B$17+Z15*Parametros!$B$16+AA15*Parametros!$B$15=K15,"OK","ERROR") -> OK
A16: API-1822 | B16: Ready for prod | C16: 2 | D16: Terminada | E16: 24 | F16: 24 | G16: =ROUND(E16*(1+Parametros!$B$4),6) -> 31.2 | H16: =INT(G16/Parametros!$B$6) -> 0 | I16: =ROUND(G16-H16*Parametros!$B$6,6) -> 31.2 | J16: =IF(I16>0,COUNTIF(Parametros!$C$15:$C$19,"<"&I16)+1,0) -> 5 | K16: =H16*Parametros!$B$19+IF(J16>0,INDEX(Parametros!$B$15:$B$19,J16),0) -> 8 | L16: =ROUND(F16*(1+Parametros!$B$4),6) -> 31.2 | M16: =INT(L16/Parametros!$B$6) -> 0 | N16: =ROUND(L16-M16*Parametros!$B$6,6) -> 31.2 | O16: =IF(N16>0,COUNTIF(Parametros!$C$15:$C$19,"<"&N16)+1,0) -> 5 | P16: =M16*Parametros!$B$19+IF(O16>0,INDEX(Parametros!$B$15:$B$19,O16),0) -> 8 | Q16: =M16+IF(O16=5,1,0) -> 1 | R16: =IF(O16=4,1,0) -> 0 | S16: =IF(O16=3,1,0) -> 0 | T16: =IF(O16=2,1,0) -> 0 | U16: =IF(O16=1,1,0) -> 0 | V16: =IF(Q16*Parametros!$B$19+R16*Parametros!$B$18+S16*Parametros!$B$17+T16*Parametros!$B$16+U16*Parametros!$B$15=P16,"OK","ERROR") -> OK | W16: =H16+IF(J16=5,1,0) -> 1 | X16: =IF(J16=4,1,0) -> 0 | Y16: =IF(J16=3,1,0) -> 0 | Z16: =IF(J16=2,1,0) -> 0 | AA16: =IF(J16=1,1,0) -> 0 | AB16: =IF(W16*Parametros!$B$19+X16*Parametros!$B$18+Y16*Parametros!$B$17+Z16*Parametros!$B$16+AA16*Parametros!$B$15=K16,"OK","ERROR") -> OK
... A30: API-1920 | B30: En curso | C30: 1 | D30: Otra | E30: 16 | F30: 16 | G30: =ROUND(E30*(1+Parametros!$B$4),6) -> 20.8 | H30: =INT(G30/Parametros!$B$6) -> 0 | I30: =ROUND(G30-H30*Parametros!$B$6,6) -> 20.8 | J30: =IF(I30>0,COUNTIF(Parametros!$C$15:$C$19,"<"&I30)+1,0) -> 4 | K30: =H30*Parametros!$B$19+IF(J30>0,INDEX(Parametros!$B$15:$B$19,J30),0) -> 5 | L30: =ROUND(F30*(1+Parametros!$B$4),6) -> 20.8 | M30: =INT(L30/Parametros!$B$6) -> 0 | N30: =ROUND(L30-M30*Parametros!$B$6,6) -> 20.8 | O30: =IF(N30>0,COUNTIF(Parametros!$C$15:$C$19,"<"&N30)+1,0) -> 4 | P30: =M30*Parametros!$B$19+IF(O30>0,INDEX(Parametros!$B$15:$B$19,O30),0) -> 5 | Q30: =M30+IF(O30=5,1,0) -> 0 | R30: =IF(O30=4,1,0) -> 1 | S30: =IF(O30=3,1,0) -> 0 | T30: =IF(O30=2,1,0) -> 0 | U30: =IF(O30=1,1,0) -> 0 | V30: =IF(Q30*Parametros!$B$19+R30*Parametros!$B$18+S30*Parametros!$B$17+T30*Parametros!$B$16+U30*Parametros!$B$15=P30,"OK","ERROR") -> OK | W30: =H30+IF(J30=5,1,0) -> 0 | X30: =IF(J30=4,1,0) -> 1 | Y30: =IF(J30=3,1,0) -> 0 | Z30: =IF(J30=2,1,0) -> 0 | AA30: =IF(J30=1,1,0) -> 0 | AB30: =IF(W30*Parametros!$B$19+X30*Parametros!$B$18+Y30*Parametros!$B$17+Z30*Parametros!$B$16+AA30*Parametros!$B$15=K30,"OK","ERROR") -> OK

Sheet Septiembre
A1: Septiembre de 2026 en tallas: la base del plan Inicial
A2: Equipo de referencia: Generic API (Viva Aerobus). Tareas terminadas = «Finalizada»/«Finalizado» o «Ready for prod» en el informe, solo horas del equipo.
A3: Cifra | B3: Valor
A4: Tareas terminadas | B4: =COUNTIF(Tareas!$D$5:$D$30,"Terminada") -> 19
A5: Horas completas de las terminadas (H+I) | B5: =SUMIFS(Tareas!$E$5:$E$30,Tareas!$D$5:$D$30,"Terminada") -> 564
A6: Horas de septiembre de las terminadas (I) | B6: =SUMIFS(Tareas!$F$5:$F$30,Tareas!$D$5:$D$30,"Terminada") -> 394
A7: Horas de septiembre de otras tareas (en curso, feedback, pausadas) | B7: =SUMIFS(Tareas!$F$5:$F$30,Tareas!$D$5:$D$30,"Otra") -> 130
A8: Horas totales reportadas en septiembre | B8: =B6+B7 -> 524
A9: Puntos, valor completo de las terminadas | B9: =SUMIFS(Tareas!$K$5:$K$30,Tareas!$D$5:$D$30,"Terminada") -> 164
A10: Puntos de septiembre de las terminadas = base del plan Inicial | B10: =SUMIFS(Tareas!$P$5:$P$30,Tareas!$D$5:$D$30,"Terminada") -> 117
A11: Puntos de septiembre de otras tareas | B11: =SUMIFS(Tareas!$P$5:$P$30,Tareas!$D$5:$D$30,"Otra") -> 36
A12: Capacidad real del mes (puntos de todas las horas) | B12: =B10+B11 -> 153
A13: Horas de trabajo por punto (terminadas) | B13: =B6/B10 -> 3.3675214
A14: Control: capacidad real x 3 de 4 semanas | B14: =B12*3/4 -> 114.75
A15: Diferencia contra la base del plan (117 - control) | B15: =B10-B14 -> 2.25
A18: Talla | B18: Puntos | C18: Cantidad en septiembre | D18: Puntos | E18: % de los puntos
A19: XL | B19: =Parametros!$B$19 -> 8 | C19: =SUMIFS(Tareas!$Q$5:$Q$30,Tareas!$D$5:$D$30,"Terminada") -> 10 | D19: =B19*C19 -> 80 | E19: =D19/$D$24 -> 0.68376068
A20: L | B20: =Parametros!$B$18 -> 5 | C20: =SUMIFS(Tareas!$R$5:$R$30,Tareas!$D$5:$D$30,"Terminada") -> 4 | D20: =B20*C20 -> 20 | E20: =D20/$D$24 -> 0.17094017
A21: M | B21: =Parametros!$B$17 -> 3 | C21: =SUMIFS(Tareas!$S$5:$S$30,Tareas!$D$5:$D$30,"Terminada") -> 1 | D21: =B21*C21 -> 3 | E21: =D21/$D$24 -> 0.025641026
A22: S | B22: =Parametros!$B$16 -> 2 | C22: =SUMIFS(Tareas!$T$5:$T$30,Tareas!$D$5:$D$30,"Terminada") -> 5 | D22: =B22*C22 -> 10 | E22: =D22/$D$24 -> 0.085470085
A23: XS | B23: =Parametros!$B$15 -> 1 | C23: =SUMIFS(Tareas!$U$5:$U$30,Tareas!$D$5:$D$30,"Terminada") -> 4 | D23: =B23*C23 -> 4 | E23: =D23/$D$24 -> 0.034188034
A24: Total | C24: =SUM(C19:C23) -> 24 | D24: =SUM(D19:D23) -> 117 | E24: =SUM(E19:E23) -> 1
A25: Control: puntos por talla = puntos de septiembre de las terminadas | B25: =IF(D24=B10,"OK","ERROR") -> OK
A28: Por integrante (anónimo) | B28: Terminadas | C28: Otras | D28: Total puntos | E28: Horas sept.
A29: Integrante 1 | B29: =SUMIFS(Tareas!$P$5:$P$30,Tareas!$C$5:$C$30,1,Tareas!$D$5:$D$30,"Terminada") -> 46 | C29: =SUMIFS(Tareas!$P$5:$P$30,Tareas!$C$5:$C$30,1,Tareas!$D$5:$D$30,"Otra") -> 5 | D29: =B29+C29 -> 51 | E29: =SUMIFS(Tareas!$F$5:$F$30,Tareas!$C$5:$C$30,1) -> 176
A30: Integrante 2 | B30: =SUMIFS(Tareas!$P$5:$P$30,Tareas!$C$5:$C$30,2,Tareas!$D$5:$D$30,"Terminada") -> 44 | C30: =SUMIFS(Tareas!$P$5:$P$30,Tareas!$C$5:$C$30,2,Tareas!$D$5:$D$30,"Otra") -> 8 | D30: =B30+C30 -> 52 | E30: =SUMIFS(Tareas!$F$5:$F$30,Tareas!$C$5:$C$30,2) -> 176
A31: Integrante 3 | B31: =SUMIFS(Tareas!$P$5:$P$30,Tareas!$C$5:$C$30,3,Tareas!$D$5:$D$30,"Terminada") -> 27 | C31: =SUMIFS(Tareas!$P$5:$P$30,Tareas!$C$5:$C$30,3,Tareas!$D$5:$D$30,"Otra") -> 23 | D31: =B31+C31 -> 50 | E31: =SUMIFS(Tareas!$F$5:$F$30,Tareas!$C$5:$C$30,3) -> 172
A32: Total | B32: =SUM(B29:B31) -> 117 | C32: =SUM(C29:C31) -> 36 | D32: =SUM(D29:D31) -> 153 | E32: =SUM(E29:E31) -> 524
A33: El reparto real fue desigual en las tareas terminadas; con todo el esfuerzo del mes quedó parejo. El plan reparte 39 puntos por persona como objetivo.

Sheet Planes
A1: Capacidad de cada plan
A2: Plan = personas x puntos por persona. Se sube o baja de plan sumando o quitando una persona.
A3: Plan | B3: Personas | C3: Puntos por persona | D3: Capacidad (pts)
A4: Inicial | B4: 3 | C4: =Parametros!$B$7 -> 39 | D4: =B4*C4 -> 117
A5: Profesional | B5: 4 | C5: =Parametros!$B$7 -> 39 | D5: =B5*C5 -> 156
A6: Alta velocidad | B6: 5 | C6: =Parametros!$B$7 -> 39 | D6: =B6*C6 -> 195
A8: Máximo de características si todo el mes fuera de una sola talla
A9: Plan | B9: XS | C9: S | D9: M | E9: L | F9: XL
A10: Inicial | B10: =INT($D4/Parametros!$B$15) -> 117 | C10: =INT($D4/Parametros!$B$16) -> 58 | D10: =INT($D4/Parametros!$B$17) -> 39 | E10: =INT($D4/Parametros!$B$18) -> 23 | F10: =INT($D4/Parametros!$B$19) -> 14
A11: Profesional | B11: =INT($D5/Parametros!$B$15) -> 156 | C11: =INT($D5/Parametros!$B$16) -> 78 | D11: =INT($D5/Parametros!$B$17) -> 52 | E11: =INT($D5/Parametros!$B$18) -> 31 | F11: =INT($D5/Parametros!$B$19) -> 19
A12: Alta velocidad | B12: =INT($D6/Parametros!$B$15) -> 195 | C12: =INT($D6/Parametros!$B$16) -> 97 | D12: =INT($D6/Parametros!$B$17) -> 65 | E12: =INT($D6/Parametros!$B$18) -> 39 | F12: =INT($D6/Parametros!$B$19) -> 24
A14: Puntos que ocupa ese máximo
A15: Plan | B15: XS | C15: S | D15: M | E15: L | F15: XL
A16: Inicial | B16: =B10*Parametros!$B$15 -> 117 | C16: =C10*Parametros!$B$16 -> 116 | D16: =D10*Parametros!$B$17 -> 117 | E16: =E10*Parametros!$B$18 -> 115 | F16: =F10*Parametros!$B$19 -> 112
A17: Profesional | B17: =B11*Parametros!$B$15 -> 156 | C17: =C11*Parametros!$B$16 -> 156 | D17: =D11*Parametros!$B$17 -> 156 | E17: =E11*Parametros!$B$18 -> 155 | F17: =F11*Parametros!$B$19 -> 152
A18: Alta velocidad | B18: =B12*Parametros!$B$15 -> 195 | C18: =C12*Parametros!$B$16 -> 194 | D18: =D12*Parametros!$B$17 -> 195 | E18: =E12*Parametros!$B$18 -> 195 | F18: =F12*Parametros!$B$19 -> 192
A20: Puntos que sobran (la capacidad no divide exacto)
A21: Plan | B21: XS | C21: S | D21: M | E21: L | F21: XL
A22: Inicial | B22: =$D4-B16 -> 0 | C22: =$D4-C16 -> 1 | D22: =$D4-D16 -> 0 | E22: =$D4-E16 -> 2 | F22: =$D4-F16 -> 5
A23: Profesional | B23: =$D5-B17 -> 0 | C23: =$D5-C17 -> 0 | D23: =$D5-D17 -> 0 | E23: =$D5-E17 -> 1 | F23: =$D5-F17 -> 4
A24: Alta velocidad | B24: =$D6-B18 -> 0 | C24: =$D6-C18 -> 1 | D24: =$D6-D18 -> 0 | E24: =$D6-E18 -> 0 | F24: =$D6-F18 -> 3
A26: Se dice «M» como referencia porque divide exacto en los tres planes.
A28: Horas de trabajo equivalentes
A29: Plan | B29: Horas de trabajo del plan | C29: Horas disponibles | D29: % de la jornada
A30: Inicial | B30: =D4*Septiembre!$B$13 -> 394 | C30: =B4*Parametros!$B$11 -> 504 | D30: =B30/C30 -> 0.78174603
A31: Profesional | B31: =D5*Septiembre!$B$13 -> 525.33333 | C31: =B5*Parametros!$B$11 -> 672 | D31: =B31/C31 -> 0.78174603
A32: Alta velocidad | B32: =D6*Septiembre!$B$13 -> 656.66667 | C32: =B6*Parametros!$B$11 -> 840 | D32: =B32/C32 -> 0.78174603
A34: Horas del plan = puntos x horas por punto de septiembre (394 h / 117 pts). Cuadra con que solo cuenten 3 de las 4 semanas.

Sheet Mezclas
A1: Mezclas posibles por plan
A2: Cada mezcla (azul = entrada) debe sumar exactamente la capacidad del plan. Los % muestran qué parte de los puntos ocupa cada talla. Horas: con el punto medio de cada talla, toda mezcla debe pedir un esfuerzo parecido al del plan (±5 %) y caber en el mes. Las horas máximas son el caso extremo (todas en el tope de su talla): solo informativas.
A4: 1. Perfil de septiembre: Como trabajó el equipo de referencia: pocas características grandes.
A5: Talla | B5: Puntos | C5: Inicial | D5: Profesional | E5: Alta velocidad | F5: % pts Inicial | G5: % pts Profesional | H5: % pts Alta velocidad | I5: % pts septiembre
A6: XL | B6: =Parametros!$B$19 -> 8 | C6: 10 | D6: 13 | E6: 16 | F6: =C6*$B6/C$13 -> 0.68376068 | G6: =D6*$B6/D$13 -> 0.66666667 | H6: =E6*$B6/E$13 -> 0.65641026 | I6: =Septiembre!E19 -> 0.68376068
A7: L | B7: =Parametros!$B$18 -> 5 | C7: 4 | D7: 6 | E7: 7 | F7: =C7*$B7/C$13 -> 0.17094017 | G7: =D7*$B7/D$13 -> 0.19230769 | H7: =E7*$B7/E$13 -> 0.17948718 | I7: =Septiembre!E20 -> 0.17094017
A8: M | B8: =Parametros!$B$17 -> 3 | C8: 1 | D8: 1 | E8: 2 | F8: =C8*$B8/C$13 -> 0.025641026 | G8: =D8*$B8/D$13 -> 0.019230769 | H8: =E8*$B8/E$13 -> 0.030769231 | I8: =Septiembre!E21 -> 0.025641026
A9: S | B9: =Parametros!$B$16 -> 2 | C9: 5 | D9: 7 | E9: 9 | F9: =C9*$B9/C$13 -> 0.085470085 | G9: =D9*$B9/D$13 -> 0.08974359 | H9: =E9*$B9/E$13 -> 0.092307692 | I9: =Septiembre!E22 -> 0.085470085
A10: XS | B10: =Parametros!$B$15 -> 1 | C10: 4 | D10: 5 | E10: 8 | F10: =C10*$B10/C$13 -> 0.034188034 | G10: =D10*$B10/D$13 -> 0.032051282 | H10: =E10*$B10/E$13 -> 0.041025641 | I10: =Septiembre!E23 -> 0.034188034
A11: Total características | C11: =SUM(C6:C10) -> 24 | D11: =SUM(D6:D10) -> 32 | E11: =SUM(E6:E10) -> 42
A13: Total puntos | C13: =SUMPRODUCT($B6:$B10,C6:C10) -> 117 | D13: =SUMPRODUCT($B6:$B10,D6:D10) -> 156 | E13: =SUMPRODUCT($B6:$B10,E6:E10) -> 195
A14: Capacidad del plan | C14: =Planes!$D$4 -> 117 | D14: =Planes!$D$5 -> 156 | E14: =Planes!$D$6 -> 195
A15: ¿Cuadra? | C15: =IF(C13=C14,"OK","ERROR") -> OK | D15: =IF(D13=D14,"OK","ERROR") -> OK | E15: =IF(E13=E14,"OK","ERROR") -> OK
A16: Horas de trabajo estimadas (punto medio de cada talla) | C16: =C6*Parametros!$G$19+C7*Parametros!$G$18+C8*Parametros!$G$17+C9*Parametros!$G$16+C10*Parametros!$G$15 -> 379.61538 | D16: =D6*Parametros!$G$19+D7*Parametros!$G$18+D8*Parametros!$G$17+D9*Parametros!$G$16+D10*Parametros!$G$15 -> 506.92308 | E16: =E6*Parametros!$G$19+E7*Parametros!$G$18+E8*Parametros!$G$17+E9*Parametros!$G$16+E10*Parametros!$G$15 -> 632.30769
A17: Horas máximas (todas en el tope de su talla) | C17: =C6*Parametros!$D$19+C7*Parametros!$D$18+C8*Parametros!$D$17+C9*Parametros!$D$16+C10*Parametros!$D$15 -> 460 | D17: =D6*Parametros!$D$19+D7*Parametros!$D$18+D8*Parametros!$D$17+D9*Parametros!$D$16+D10*Parametros!$D$15 -> 614.61538 | E17: =E6*Parametros!$D$19+E7*Parametros!$D$18+E8*Parametros!$D$17+E9*Parametros!$D$16+E10*Parametros!$D$15 -> 770
A18: Horas equivalentes del plan (pts x h por punto de septiembre) | C18: =Planes!$B$30 -> 394 | D18: =Planes!$B$31 -> 525.33333 | E18: =Planes!$B$32 -> 656.66667
A19: Diferencia: estimadas vs equivalentes | C19: =C16/C18-1 -> -0.036509176 | D19: =D16/D18-1 -> -0.035044904 | E19: =E16/E18-1 -> -0.037094885
A20: Horas disponibles del mes (personas x 168) | C20: =Planes!$C$30 -> 504 | D20: =Planes!$C$31 -> 672 | E20: =Planes!$C$32 -> 840
A21: ¿Esfuerzo parecido (±5 %) y cabe en el mes? | C21: =IF(AND(ABS(C19)<=0.05,C16<=C20),"OK","ERROR") -> OK | D21: =IF(AND(ABS(D19)<=0.05,D16<=D20),"OK","ERROR") -> OK | E21: =IF(AND(ABS(E19)<=0.05,E16<=E20),"OK","ERROR") -> OK
A24: 2. Balanceada: Evolución normal del producto: de todo un poco.
A25: Talla | B25: Puntos | C25: Inicial | D25: Profesional | E25: Alta velocidad | F25: % pts Inicial | G25: % pts Profesional | H25: % pts Alta velocidad
A26: XL | B26: =Parametros!$B$19 -> 8 | C26: 4 | D26: 6 | E26: 8 | F26: =C26*$B26/C$33 -> 0.27350427 | G26: =D26*$B26/D$33 -> 0.30769231 | H26: =E26*$B26/E$33 -> 0.32820513
A27: L | B27: =Parametros!$B$18 -> 5 | C27: 6 | D27: 8 | E27: 10 | F27: =C27*$B27/C$33 -> 0.25641026 | G27: =D27*$B27/D$33 -> 0.25641026 | H27: =E27*$B27/E$33 -> 0.25641026
A28: M | B28: =Parametros!$B$17 -> 3 | C28: 10 | D28: 12 | E28: 15 | F28: =C28*$B28/C$33 -> 0.25641026 | G28: =D28*$B28/D$33 -> 0.23076923 | H28: =E28*$B28/E$33 -> 0.23076923
A29: S | B29: =Parametros!$B$16 -> 2 | C29: 10 | D29: 12 | E29: 14 | F29: =C29*$B29/C$33 -> 0.17094017 | G29: =D29*$B29/D$33 -> 0.15384615 | H29: =E29*$B29/E$33 -> 0.14358974
A30: XS | B30: =Parametros!$B$15 -> 1 | C30: 5 | D30: 8 | E30: 8 | F30: =C30*$B30/C$33 -> 0.042735043 | G30: =D30*$B30/D$33 -> 0.051282051 | H30: =E30*$B30/E$33 -> 0.041025641
A31: Total características | C31: =SUM(C26:C30) -> 35 | D31: =SUM(D26:D30) -> 46 | E31: =SUM(E26:E30) -> 55
A33: Total puntos | C33: =SUMPRODUCT($B26:$B30,C26:C30) -> 117 | D33: =SUMPRODUCT($B26:$B30,D26:D30) -> 156 | E33: =SUMPRODUCT($B26:$B30,E26:E30) -> 195
A34: Capacidad del plan | C34: =Planes!$D$4 -> 117 | D34: =Planes!$D$5 -> 156 | E34: =Planes!$D$6 -> 195
A35: ¿Cuadra? | C35: =IF(C33=C34,"OK","ERROR") -> OK | D35: =IF(D33=D34,"OK","ERROR") -> OK | E35: =IF(E33=E34,"OK","ERROR") -> OK
A36: Horas de trabajo estimadas (punto medio de cada talla) | C36: =C26*Parametros!$G$19+C27*Parametros!$G$18+C28*Parametros!$G$17+C29*Parametros!$G$16+C30*Parametros!$G$15 -> 391.53846 | D36: =D26*Parametros!$G$19+D27*Parametros!$G$18+D28*Parametros!$G$17+D29*Parametros!$G$16+D30*Parametros!$G$15 -> 519.23077 | E36: =E26*Parametros!$G$19+E27*Parametros!$G$18+E28*Parametros!$G$17+E29*Parametros!$G$16+E30*Parametros!$G$15 -> 650.76923
A37: Horas máximas (todas en el tope de su talla) | C37: =C26*Parametros!$D$19+C27*Parametros!$D$18+C28*Parametros!$D$17+C29*Parametros!$D$16+C30*Parametros!$D$15 -> 487.69231 | D37: =D26*Parametros!$D$19+D27*Parametros!$D$18+D28*Parametros!$D$17+D29*Parametros!$D$16+D30*Parametros!$D$15 -> 647.69231 | E37: =E26*Parametros!$D$19+E27*Parametros!$D$18+E28*Parametros!$D$17+E29*Parametros!$D$16+E30*Parametros!$D$15 -> 806.92308
A38: Horas equivalentes del plan (pts x h por punto de septiembre) | C38: =Planes!$B$30 -> 394 | D38: =Planes!$B$31 -> 525.33333 | E38: =Planes!$B$32 -> 656.66667
A39: Diferencia: estimadas vs equivalentes | C39: =C36/C38-1 -> -0.0062475595 | D39: =D36/D38-1 -> -0.011616556 | E39: =E36/E38-1 -> -0.0089808668
A40: Horas disponibles del mes (personas x 168) | C40: =Planes!$C$30 -> 504 | D40: =Planes!$C$31 -> 672 | E40: =Planes!$C$32 -> 840
A41: ¿Esfuerzo parecido (±5 %) y cabe en el mes? | C41: =IF(AND(ABS(C39)<=0.05,C36<=C40),"OK","ERROR") -> OK | D41: =IF(AND(ABS(D39)<=0.05,D36<=D40),"OK","ERROR") -> OK | E41: =IF(AND(ABS(E39)<=0.05,E36<=E40),"OK","ERROR") -> OK
A44: 3. Muchas y pequeñas: Mantenimiento, ajustes y mejoras puntuales.
A45: Talla | B45: Puntos | C45: Inicial | D45: Profesional | E45: Alta velocidad | F45: % pts Inicial | G45: % pts Profesional | H45: % pts Alta velocidad
A46: XL | B46: =Parametros!$B$19 -> 8 | C46: 0 | D46: 0 | E46: 0 | F46: =C46*$B46/C$53 -> 0 | G46: =D46*$B46/D$53 -> 0 | H46: =E46*$B46/E$53 -> 0
A47: L | B47: =Parametros!$B$18 -> 5 | C47: 2 | D47: 3 | E47: 4 | F47: =C47*$B47/C$53 -> 0.085470085 | G47: =D47*$B47/D$53 -> 0.096153846 | H47: =E47*$B47/E$53 -> 0.1025641
...

Sheet Equipo
A1: Cómo toma cada persona su parte de la mezcla
A2: Cada persona toma exactamente los puntos por persona (39). La suma del equipo debe ser igual a la mezcla. Horas estimadas = punto medio de cada talla; deben caber en el mes de la persona (42 h x 4).
A4: 1. Perfil de septiembre · Inicial (3 personas)
A5: Integrante | B5: XL | C5: L | D5: M | E5: S | F5: XS | G5: Puntos | H5: ¿Cuadra? | I5: Horas estimadas | J5: Horas máximas | K5: ¿Cabe en el mes?
A6: Persona 1 | B6: 3 | C6: 2 | D6: 0 | E6: 2 | F6: 1 | G6: =B6*Parametros!$B$19+C6*Parametros!$B$18+D6*Parametros!$B$17+E6*Parametros!$B$16+F6*Parametros!$B$15 -> 39 | H6: =IF(G6=Parametros!$B$7,"OK","ERROR") -> OK | I6: =B6*Parametros!$G$19+C6*Parametros!$G$18+D6*Parametros!$G$17+E6*Parametros!$G$16+F6*Parametros!$G$15 -> 127.30769 | J6: =B6*Parametros!$D$19+C6*Parametros!$D$18+D6*Parametros!$D$17+E6*Parametros!$D$16+F6*Parametros!$D$15 -> 154.61538 | K6: =IF(I6<=Parametros!$B$11,"OK","ERROR") -> OK
A7: Persona 2 | B7: 3 | C7: 1 | D7: 1 | E7: 2 | F7: 3 | G7: =B7*Parametros!$B$19+C7*Parametros!$B$18+D7*Parametros!$B$17+E7*Parametros!$B$16+F7*Parametros!$B$15 -> 39 | H7: =IF(G7=Parametros!$B$7,"OK","ERROR") -> OK | I7: =B7*Parametros!$G$19+C7*Parametros!$G$18+D7*Parametros!$G$17+E7*Parametros!$G$16+F7*Parametros!$G$15 -> 125.38462 | J7: =B7*Parametros!$D$19+C7*Parametros!$D$18+D7*Parametros!$D$17+E7*Parametros!$D$16+F7*Parametros!$D$15 -> 155.38462 | K7: =IF(I7<=Parametros!$B$11,"OK","ERROR") -> OK
A8: Persona 3 | B8: 4 | C8: 1 | D8: 0 | E8: 1 | F8: 0 | G8: =B8*Parametros!$B$19+C8*Parametros!$B$18+D8*Parametros!$B$17+E8*Parametros!$B$16+F8*Parametros!$B$15 -> 39 | H8: =IF(G8=Parametros!$B$7,"OK","ERROR") -> OK | I8: =B8*Parametros!$G$19+C8*Parametros!$G$18+D8*Parametros!$G$17+E8*Parametros!$G$16+F8*Parametros!$G$15 -> 126.92308 | J8: =B8*Parametros!$D$19+C8*Parametros!$D$18+D8*Parametros!$D$17+E8*Parametros!$D$16+F8*Parametros!$D$15 -> 150 | K8: =IF(I8<=Parametros!$B$11,"OK","ERROR") -> OK
A9: Suma del equipo | B9: =SUM(B6:B8) -> 10 | C9: =SUM(C6:C8) -> 4 | D9: =SUM(D6:D8) -> 1 | E9: =SUM(E6:E8) -> 5 | F9: =SUM(F6:F8) -> 4 | G9: =B9*Parametros!$B$19+C9*Parametros!$B$18+D9*Parametros!$B$17+E9*Parametros!$B$16+F9*Parametros!$B$15 -> 117
A10: Mezcla (hoja Mezclas) | B10: =Mezclas!$C$6 -> 10 | C10: =Mezclas!$C$7 -> 4 | D10: =Mezclas!$C$8 -> 1 | E10: =Mezclas!$C$9 -> 5 | F10: =Mezclas!$C$10 -> 4 | G10: =Planes!$D$4 -> 117
A11: ¿Cuadra? | B11: =IF(B9=B10,"OK","ERROR") -> OK | C11: =IF(C9=C10,"OK","ERROR") -> OK | D11: =IF(D9=D10,"OK","ERROR") -> OK | E11: =IF(E9=E10,"OK","ERROR") -> OK | F11: =IF(F9=F10,"OK","ERROR") -> OK | G11: =IF(G9=G10,"OK","ERROR") -> OK
A13: 1. Perfil de septiembre · Profesional (4 personas)
A14: Integrante | B14: XL | C14: L | D14: M | E14: S | F14: XS | G14: Puntos | H14: ¿Cuadra? | I14: Horas estimadas | J14: Horas máximas | K14: ¿Cabe en el mes?
A15: Persona 1 | B15: 3 | C15: 2 | D15: 0 | E15: 2 | F15: 1 | G15: =B15*Parametros!$B$19+C15*Parametros!$B$18+D15*Parametros!$B$17+E15*Parametros!$B$16+F15*Parametros!$B$15 -> 39 | H15: =IF(G15=Parametros!$B$7,"OK","ERROR") -> OK | I15: =B15*Parametros!$G$19+C15*Parametros!$G$18+D15*Parametros!$G$17+E15*Parametros!$G$16+F15*Parametros!$G$15 -> 127.30769 | J15: =B15*Parametros!$D$19+C15*Parametros!$D$18+D15*Parametros!$D$17+E15*Parametros!$D$16+F15*Parametros!$D$15 -> 154.61538 | K15: =IF(I15<=Parametros!$B$11,"OK","ERROR") -> OK
A16: Persona 2 | B16: 3 | C16: 2 | D16: 0 | E16: 2 | F16: 1 | G16: =B16*Parametros!$B$19+C16*Parametros!$B$18+D16*Parametros!$B$17+E16*Parametros!$B$16+F16*Parametros!$B$15 -> 39 | H16: =IF(G16=Parametros!$B$7,"OK","ERROR") -> OK | I16: =B16*Parametros!$G$19+C16*Parametros!$G$18+D16*Parametros!$G$17+E16*Parametros!$G$16+F16*Parametros!$G$15 -> 127.30769 | J16: =B16*Parametros!$D$19+C16*Parametros!$D$18+D16*Parametros!$D$17+E16*Parametros!$D$16+F16*Parametros!$D$15 -> 154.61538 | K16: =IF(I16<=Parametros!$B$11,"OK","ERROR") -> OK
A17: Persona 3 | B17: 3 | C17: 1 | D17: 1 | E17: 2 | F17: 3 | G17: =B17*Parametros!$B$19+C17*Parametros!$B$18+D17*Parametros!$B$17+E17*Parametros!$B$16+F17*Parametros!$B$15 -> 39 | H17: =IF(G17=Parametros!$B$7,"OK","ERROR") -> OK | I17: =B17*Parametros!$G$19+C17*Parametros!$G$18+D17*Parametros!$G$17+E17*Parametros!$G$16+F17*Parametros!$G$15 -> 125.38462 | J17: =B17*Parametros!$D$19+C17*Parametros!$D$18+D17*Parametros!$D$17+E17*Parametros!$D$16+F17*Parametros!$D$15 -> 155.38462 | K17: =IF(I17<=Parametros!$B$11,"OK","ERROR") -> OK
A18: Persona 4 | B18: 4 | C18: 1 | D18: 0 | E18: 1 | F18: 0 | G18: =B18*Parametros!$B$19+C18*Parametros!$B$18+D18*Parametros!$B$17+E18*Parametros!$B$16+F18*Parametros!$B$15 -> 39 | H18: =IF(G18=Parametros!$B$7,"OK","ERROR") -> OK | I18: =B18*Parametros!$G$19+C18*Parametros!$G$18+D18*Parametros!$G$17+E18*Parametros!$G$16+F18*Parametros!$G$15 -> 126.92308 | J18: =B18*Parametros!$D$19+C18*Parametros!$D$18+D18*Parametros!$D$17+E18*Parametros!$D$16+F18*Parametros!$D$15 -> 150 | K18: =IF(I18<=Parametros!$B$11,"OK","ERROR") -> OK
A19: Suma del equipo | B19: =SUM(B15:B18) -> 13 | C19: =SUM(C15:C18) -> 6 | D19: =SUM(D15:D18) -> 1 | E19: =SUM(E15:E18) -> 7 | F19: =SUM(F15:F18) -> 5 | G19: =B19*Parametros!$B$19+C19*Parametros!$B$18+D19*Parametros!$B$17+E19*Parametros!$B$16+F19*Parametros!$B$15 -> 156
A20: Mezcla (hoja Mezclas) | B20: =Mezclas!$D$6 -> 13 | C20: =Mezclas!$D$7 -> 6 | D20: =Mezclas!$D$8 -> 1 | E20: =Mezclas!$D$9 -> 7 | F20: =Mezclas!$D$10 -> 5 | G20: =Planes!$D$5 -> 156
A21: ¿Cuadra? | B21: =IF(B19=B20,"OK","ERROR") -> OK | C21: =IF(C19=C20,"OK","ERROR") -> OK | D21: =IF(D19=D20,"OK","ERROR") -> OK | E21: =IF(E19=E20,"OK","ERROR") -> OK | F21: =IF(F19=F20,"OK","ERROR") -> OK | G21: =IF(G19=G20,"OK","ERROR") -> OK
A23: 1. Perfil de septiembre · Alta velocidad (5 personas)
A24: Integrante | B24: XL | C24: L | D24: M | E24: S | F24: XS | G24: Puntos | H24: ¿Cuadra? | I24: Horas estimadas | J24: Horas máximas | K24: ¿Cabe en el mes?
A25: Persona 1 | B25: 3 | C25: 2 | D25: 0 | E25: 2 | F25: 1 | G25: =B25*Parametros!$B$19+C25*Parametros!$B$18+D25*Parametros!$B$17+E25*Parametros!$B$16+F25*Parametros!$B$15 -> 39 | H25: =IF(G25=Parametros!$B$7,"OK","ERROR") -> OK | I25: =B25*Parametros!$G$19+C25*Parametros!$G$18+D25*Parametros!$G$17+E25*Parametros!$G$16+F25*Parametros!$G$15 -> 127.30769 | J25: =B25*Parametros!$D$19+C25*Parametros!$D$18+D25*Parametros!$D$17+E25*Parametros!$D$16+F25*Parametros!$D$15 -> 154.61538 | K25: =IF(I25<=Parametros!$B$11,"OK","ERROR") -> OK
A26: Persona 2 | B26: 3 | C26: 1 | D26: 1 | E26: 2 | F26: 3 | G26: =B26*Parametros!$B$19+C26*Parametros!$B$18+D26*Parametros!$B$17+E26*Parametros!$B$16+F26*Parametros!$B$15 -> 39 | H26: =IF(G26=Parametros!$B$7,"OK","ERROR") -> OK | I26: =B26*Parametros!$G$19+C26*Parametros!$G$18+D26*Parametros!$G$17+E26*Parametros!$G$16+F26*Parametros!$G$15 -> 125.38462 | J26: =B26*Parametros!$D$19+C26*Parametros!$D$18+D26*Parametros!$D$17+E26*Parametros!$D$16+F26*Parametros!$D$15 -> 155.38462 | K26: =IF(I26<=Parametros!$B$11,"OK","ERROR") -> OK
A27: Persona 3 | B27: 3 | C27: 2 | D27: 0 | E27: 2 | F27: 1 | G27: =B27*Parametros!$B$19+C27*Parametros!$B$18+D27*Parametros!$B$17+E27*Parametros!$B$16+F27*Parametros!$B$15 -> 39 | H27: =IF(G27=Parametros!$B$7,"OK","ERROR") -> OK | I27: =B27*Parametros!$G$19+C27*Parametros!$G$18+D27*Parametros!$G$17+E27*Parametros!$G$16+F27*Parametros!$G$15 -> 127.30769 | J27: =B27*Parametros!$D$19+C27*Parametros!$D$18+D27*Parametros!$D$17+E27*Parametros!$D$16+F27*Parametros!$D$15 -> 154.61538 | K27: =IF(I27<=Parametros!$B$11,"OK","ERROR") -> OK
A28: Persona 4 | B28: 3 | C28: 1 | D28: 1 | E28: 2 | F28: 3 | G28: =B28*Parametros!$B$19+C28*Parametros!$B$18+D28*Parametros!$B$17+E28*Parametros!$B$16+F28*Parametros!$B$15 -> 39 | H28: =IF(G28=Parametros!$B$7,"OK","ERROR") -> OK | I28: =B28*Parametros!$G$19+C28*Parametros!$G$18+D28*Parametros!$G$17+E28*Parametros!$G$16+F28*Parametros!$G$15 -> 125.38462 | J28: =B28*Parametros!$D$19+C28*Parametros!$D$18+D28*Parametros!$D$17+E28*Parametros!$D$16+F28*Parametros!$D$15 -> 155.38462 | K28: =IF(I28<=Parametros!$B$11,"OK","ERROR") -> OK
A29: Persona 5 | B29: 4 | C29: 1 | D29: 0 | E29: 1 | F29: 0 | G29: =B29*Parametros!$B$19+C29*Parametros!$B$18+D29*Parametros!$B$17+E29*Parametros!$B$16+F29*Parametros!$B$15 -> 39 | H29: =IF(G29=Parametros!$B$7,"OK","ERROR") -> OK | I29: =B29*Parametros!$G$19+C29*Parametros!$G$18+D29*Parametros!$G$17+E29*Parametros!$G$16+F29*Parametros!$G$15 -> 126.92308 | J29: =B29*Parametros!$D$19+C29*Parametros!$D$18+D29*Parametros!$D$17+E29*Parametros!$D$16+F29*Parametros!$D$15 -> 150 | K29: =IF(I29<=Parametros!$B$11,"OK","ERROR") -> OK
A30: Suma del equipo | B30: =SUM(B25:B29) -> 16 | C30: =SUM(C25:C29) -> 7 | D30: =SUM(D25:D29) -> 2 | E30: =SUM(E25:E29) -> 9 | F30: =SUM(F25:F29) -> 8 | G30: =B30*Parametros!$B$19+C30*Parametros!$B$18+D30*Parametros!$B$17+E30*Parametros!$B$16+F30*Parametros!$B$15 -> 195
A31: Mezcla (hoja Mezclas) | B31: =Mezclas!$E$6 -> 16 | C31: =Mezclas!$E$7 -> 7 | D31: =Mezclas!$E$8 -> 2 | E31: =Mezclas!$E$9 -> 9 | F31: =Mezclas!$E$10 -> 8 | G31: =Planes!$D$6 -> 195
A32: ¿Cuadra? | B32: =IF(B30=B31,"OK","ERROR") -> OK | C32: =IF(C30=C31,"OK","ERROR") -> OK | D32: =IF(D30=D31,"OK","ERROR") -> OK | E32: =IF(E30=E31,"OK","ERROR") -> OK | F32: =IF(F30=F31,"OK","ERROR") -> OK | G32: =IF(G30=G31,"OK","ERROR") -> OK
A34: 2. Balanceada · Inicial (3 personas)
A35: Integrante | B35: XL | C35: L | D35: M | E35: S | F35: XS | G35: Puntos | H35: ¿Cuadra? | I35: Horas estimadas | J35: Horas máximas | K35: ¿Cabe en el mes?
A36: Persona 1 | B36: 1 | C36: 2 | D36: 4 | E36: 4 | F36: 1 | G36: =B36*Parametros!$B$19+C36*Parametros!$B$18+D36*Parametros!$B$17+E36*Parametros!$B$16+F36*Parametros!$B$15 -> 39 | H36: =IF(G36=Parametros!$B$7,"OK","ERROR") -> OK | I36: =B36*Parametros!$G$19+C36*Parametros!$G$18+D36*Parametros!$G$17+E36*Parametros!$G$16+F36*Parametros!$G$15 -> 131.92308 | J36: =B36*Parametros!$D$19+C36*Parametros!$D$18+D36*Parametros!$D$17+E36*Parametros!$D$16+F36*Parametros!$D$15 -> 163.84615 | K36: =IF(I36<=Parametros!$B$11,"OK","ERROR") -> OK
A37: Persona 2 | B37: 1 | C37: 2 | D37: 3 | E37: 5 | F37: 2 | G37: =B37*Parametros!$B$19+C37*Parametros!$B$18+D37*Parametros!$B$17+E37*Parametros!$B$16+F37*Parametros!$B$15 -> 39 | H37: =IF(G37=Parametros!$B$7,"OK","ERROR") -> OK | I37: =B37*Parametros!$G$19+C37*Parametros!$G$18+D37*Parametros!$G$17+E37*Parametros!$G$16+F37*Parametros!$G$15 -> 130 | J37: =B37*Parametros!$D$19+C37*Parametros!$D$18+D37*Parametros!$D$17+E37*Parametros!$D$16+F37*Parametros!$D$15 -> 163.84615 | K37: =IF(I37<=Parametros!$B$11,"OK","ERROR") -> OK
A38: Persona 3 | B38: 2 | C38: 2 | D38: 3 | E38: 1 | F38: 2 | G38: =B38*Parametros!$B$19+C38*Parametros!$B$18+D38*Parametros!$B$17+E38*Parametros!$B$16+F38*Parametros!$B$15 -> 39 | H38: =IF(G38=Parametros!$B$7,"OK","ERROR") -> OK | I38: =B38*Parametros!$G$19+C38*Parametros!$G$18+D38*Parametros!$G$17+E38*Parametros!$G$16+F38*Parametros!$G$15 -> 129.61538 | J38: =B38*Parametros!$D$19+C38*Parametros!$D$18+D38*Parametros!$D$17+E38*Parametros!$D$16+F38*Parametros!$D$15 -> 160 | K38: =IF(I38<=Parametros!$B$11,"OK","ERROR") -> OK
A39: Suma del equipo | B39: =SUM(B36:B38) -> 4 | C39: =SUM(C36:C38) -> 6 | D39: =SUM(D36:D38) -> 10 | E39: =SUM(E36:E38) -> 10 | F39: =SUM(F36:F38) -> 5 | G39: =B39*Parametros!$B$19+C39*Parametros!$B$18+D39*Parametros!$B$17+E39*Parametros!$B$16+F39*Parametros!$B$15 -> 117
A40: Mezcla (hoja Mezclas) | B40: =Mezclas!$C$26 -> 4 | C40: =Mezclas!$C$27 -> 6 | D40: =Mezclas!$C$28 -> 10 | E40: =Mezclas!$C$29 -> 10 | F40: =Mezclas!$C$30 -> 5 | G40: =Planes!$D$4 -> 117
A41: ¿Cuadra? | B41: =IF(B39=B40,"OK","ERROR") -> OK | C41: =IF(C39=C40,"OK","ERROR") -> OK | D41: =IF(D39=D40,"OK","ERROR") -> OK | E41: =IF(E39=E40,"OK","ERROR") -> OK | F41: =IF(F39=F40,"OK","ERROR") -> OK | G41: =IF(G39=G40,"OK","ERROR") -> OK
A43: 2. Balanceada · Profesional (4 personas)
A44: Integrante | B44: XL | C44: L | D44: M | E44: S | F44: XS | G44: Puntos | H44: ¿Cuadra? | I44: Horas estimadas | J44: Horas máximas | K44: ¿Cabe en el mes?
A45: Persona 1 | B45: 1 | C45: 2 | D45: 3 | E45: 5 | F45: 2 | G45: =B45*Parametros!$B$19+C45*Parametros!$B$18+D45*Parametros!$B$17+E45*Parametros!$B$16+F45*Parametros!$B$15 -> 39 | H45: =IF(G45=Parametros!$B$7,"OK","ERROR") -> OK | I45: =B45*Parametros!$G$19+C45*Parametros!$G$18+D45*Parametros!$G$17+E45*Parametros!$G$16+F45*Parametros!$G$15 -> 130 | J45: =B45*Parametros!$D$19+C45*Parametros!$D$18+D45*Parametros!$D$17+E45*Parametros!$D$16+F45*Parametros!$D$15 -> 163.84615 | K45: =IF(I45<=Parametros!$B$11,"OK","ERROR") -> OK
...

Sheet Verificacion
A1: Verificación de todos los cálculos
A2: Esperado = valor del informe de septiembre de 2026 o de la regla acordada. Todo debe decir OK.
A3: Control | B3: Calculado | C3: Esperado | D3: ¿Cuadra?
A4: Tareas terminadas del equipo | B4: =Septiembre!B4 -> 19 | C4: 19 | D4: =IF(B4=C4,"OK","ERROR") -> OK
A5: Horas completas de las terminadas | B5: =Septiembre!B5 -> 564 | C5: 564 | D5: =IF(B5=C5,"OK","ERROR") -> OK
A6: Horas de septiembre de las terminadas | B6: =Septiembre!B6 -> 394 | C6: 394 | D6: =IF(B6=C6,"OK","ERROR") -> OK
A7: Horas de septiembre de otras tareas | B7: =Septiembre!B7 -> 130 | C7: 130 | D7: =IF(B7=C7,"OK","ERROR") -> OK
A8: Horas totales reportadas en septiembre | B8: =Septiembre!B8 -> 524 | C8: 524 | D8: =IF(B8=C8,"OK","ERROR") -> OK
A9: Puntos, valor completo de las terminadas | B9: =Septiembre!B9 -> 164 | C9: 164 | D9: =IF(B9=C9,"OK","ERROR") -> OK
A10: Puntos de septiembre de las terminadas | B10: =Septiembre!B10 -> 117 | C10: 117 | D10: =IF(B10=C10,"OK","ERROR") -> OK
A11: Capacidad real del mes (puntos) | B11: =Septiembre!B12 -> 153 | C11: 153 | D11: =IF(B11=C11,"OK","ERROR") -> OK
A12: Puntos por persona | B12: =Parametros!B7 -> 39 | C12: 39 | D12: =IF(B12=C12,"OK","ERROR") -> OK
A13: Capacidad Inicial | B13: =Planes!D4 -> 117 | C13: 117 | D13: =IF(B13=C13,"OK","ERROR") -> OK
A14: Capacidad Profesional | B14: =Planes!D5 -> 156 | C14: 156 | D14: =IF(B14=C14,"OK","ERROR") -> OK
A15: Capacidad Alta velocidad | B15: =Planes!D6 -> 195 | C15: 195 | D15: =IF(B15=C15,"OK","ERROR") -> OK
A16: Características de septiembre por talla: XL | B16: =Septiembre!C19 -> 10 | C16: 10 | D16: =IF(B16=C16,"OK","ERROR") -> OK
A17: Características de septiembre por talla: L | B17: =Septiembre!C20 -> 4 | C17: 4 | D17: =IF(B17=C17,"OK","ERROR") -> OK
A18: Características de septiembre por talla: M | B18: =Septiembre!C21 -> 1 | C18: 1 | D18: =IF(B18=C18,"OK","ERROR") -> OK
A19: Características de septiembre por talla: S | B19: =Septiembre!C22 -> 5 | C19: 5 | D19: =IF(B19=C19,"OK","ERROR") -> OK
A20: Características de septiembre por talla: XS | B20: =Septiembre!C23 -> 4 | C20: 4 | D20: =IF(B20=C20,"OK","ERROR") -> OK
A21: Controles de cada tarea (sept. y completa): 26 tareas x 2 | B21: =COUNTIF(Tareas!V5:V30,"OK")+COUNTIF(Tareas!AB5:AB30,"OK") -> 52 | C21: 52 | D21: =IF(B21=C21,"OK","ERROR") -> OK
A22: Mezclas que llenan su plan (3 mezclas x 3 planes) | B22: =COUNTIF(Mezclas!C15,"OK")+COUNTIF(Mezclas!D15,"OK")+COUNTIF(Mezclas!E15,"OK")+COUNTIF(Mezclas!C35,"OK")+COUNTIF(Mezclas!D35,"OK")+COUNTIF(Mezclas!E35,"OK")+COUNTIF(Mezclas!C55,"OK")+COUNTIF(Mezclas!D55,"OK")+COUNTIF(Mezclas!E55,"OK") -> 9 | C22: 9 | D22: =IF(B22=C22,"OK","ERROR") -> OK
A23: Controles del reparto por persona y por talla | B23: =COUNTIF(Equipo!H6,"OK")+COUNTIF(Equipo!H7,"OK")+COUNTIF(Equipo!H8,"OK")+COUNTIF(Equipo!B11,"OK")+COUNTIF(Equipo!C11,"OK")+COUNTIF(Equipo!D11,"OK")+COUNTIF(Equipo!E11,"OK")+COUNTIF(Equipo!F11,"OK")+COUNTIF(Equipo!G11,"OK")+COUNTIF(Equipo!H15,"OK")+COUNTIF(Equipo!H16,"OK")+COUNTIF(Equipo!H17,"OK")+COUNTIF(Equipo!H18,"OK")+COUNTIF(Equipo!B21,"OK")+COUNTIF(Equipo!C21,"OK")+COUNTIF(Equipo!D21,"OK")+COUNTIF(Equipo!E21,"OK")+COUNTIF(Equipo!F21,"OK")+COUNTIF(Equipo!G21,"OK")+COUNTIF(Equipo!H25,"OK")+COUNTIF(Equipo!H26,"OK")+COUNTIF(Equipo!H27,"OK")+COUNTIF(Equipo!H28,"OK")+COUNTIF(Equipo!H29,"OK")+COUNTIF(Equipo!B32,"OK")+COUNTIF(Equipo!C32,"OK")+COUNTIF(Equipo!D32,"OK")+COUNTIF(Equipo!E32,"OK")+COUNTIF(Equipo!F32,"OK")+COUNTIF(Equipo!G32,"OK")+COUNTIF(Equipo!H36,"OK")+COUNTIF(Equipo!H37,"OK")+COUNTIF(Equipo!H38,"OK")+COUNTIF(Equipo!B41,"OK")+COUNTIF(Equipo!C41,"OK")+COUNTIF(Equipo!D41,"OK")+COUNTIF(Equipo!E41,"OK")+COUNTIF(Equipo!F41,"OK")+COUNTIF(Equipo!G41,"OK")+COUNTIF(Equipo!H45,"OK")+COUNTIF(Equipo!H46,"OK")+COUNTIF(Equipo!H47,"OK")+COUNTIF(Equipo!H48,"OK")+COUNTIF(Equipo!B51,"OK")+COUNTIF(Equipo!C51,"OK")+COUNTIF(Equipo!D51,"OK")+COUNTIF(Equipo!E51,"OK")+COUNTIF(Equipo!F51,"OK")+COUNTIF(Equipo!G51,"OK")+COUNTIF(Equipo!H55,"OK")+COUNTIF(Equipo!H56,"OK")+COUNTIF(Equipo!H57,"OK")+COUNTIF(Equipo!H58,"OK")+COUNTIF(Equipo!H59,"OK")+COUNTIF(Equipo!B62,"OK")+COUNTIF(Equipo!C62,"OK")+COUNTIF(Equipo!D62,"OK")+COUNTIF(Equipo!E62,"OK")+COUNTIF(Equipo!F62,"OK")+COUNTIF(Equipo!G62,"OK")+COUNTIF(Equipo!H66,"OK")+COUNTIF(Equipo!H67,"OK")+COUNTIF(Equipo!H68,"OK")+COUNTIF(Equipo!B71,"OK")+COUNTIF(Equipo!C71,"OK")+COUNTIF(Equipo!D71,"OK")+COUNTIF(Equipo!E71,"OK")+COUNTIF(Equipo!F71,"OK")+COUNTIF(Equipo!G71,"OK")+COUNTIF(Equipo!H75,"OK")+COUNTIF(Equipo!H76,"OK")+COUNTIF(Equipo!H77,"OK")+COUNTIF(Equipo!H78,"OK")+COUNTIF(Equipo!B81,"OK")+COUNTIF(Equipo!C81,"OK")+COUNTIF(Equipo!D81,"OK")+COUNTIF(Equipo!E81,"OK")+COUNTIF(Equipo!F81,"OK")+COUNTIF(Equipo!G81,"OK")+COUNTIF(Equipo!H85,"OK")+COUNTIF(Equipo!H86,"OK")+COUNTIF(Equipo!H87,"OK")+COUNTIF(Equipo!H88,"OK")+COUNTIF(Equipo!H89,"OK")+COUNTIF(Equipo!B92,"OK")+COUNTIF(Equipo!C92,"OK")+COUNTIF(Equipo!D92,"OK")+COUNTIF(Equipo!E92,"OK")+COUNTIF(Equipo!F92,"OK")+COUNTIF(Equipo!G92,"OK") -> 90 | C23: 90 | D23: =IF(B23=C23,"OK","ERROR") -> OK
A24: Mezclas con esfuerzo parecido al del plan (±5 %) que caben en el mes | B24: =COUNTIF(Mezclas!C21,"OK")+COUNTIF(Mezclas!D21,"OK")+COUNTIF(Mezclas!E21,"OK")+COUNTIF(Mezclas!C41,"OK")+COUNTIF(Mezclas!D41,"OK")+COUNTIF(Mezclas!E41,"OK")+COUNTIF(Mezclas!C61,"OK")+COUNTIF(Mezclas!D61,"OK")+COUNTIF(Mezclas!E61,"OK") -> 9 | C24: 9 | D24: =IF(B24=C24,"OK","ERROR") -> OK
A25: Personas cuyo esfuerzo estimado cabe en su mes (42 h x 4) | B25: =COUNTIF(Equipo!K6,"OK")+COUNTIF(Equipo!K7,"OK")+COUNTIF(Equipo!K8,"OK")+COUNTIF(Equipo!K15,"OK")+COUNTIF(Equipo!K16,"OK")+COUNTIF(Equipo!K17,"OK")+COUNTIF(Equipo!K18,"OK")+COUNTIF(Equipo!K25,"OK")+COUNTIF(Equipo!K26,"OK")+COUNTIF(Equipo!K27,"OK")+COUNTIF(Equipo!K28,"OK")+COUNTIF(Equipo!K29,"OK")+COUNTIF(Equipo!K36,"OK")+COUNTIF(Equipo!K37,"OK")+COUNTIF(Equipo!K38,"OK")+COUNTIF(Equipo!K45,"OK")+COUNTIF(Equipo!K46,"OK")+COUNTIF(Equipo!K47,"OK")+COUNTIF(Equipo!K48,"OK")+COUNTIF(Equipo!K55,"OK")+COUNTIF(Equipo!K56,"OK")+COUNTIF(Equipo!K57,"OK")+COUNTIF(Equipo!K58,"OK")+COUNTIF(Equipo!K59,"OK")+COUNTIF(Equipo!K66,"OK")+COUNTIF(Equipo!K67,"OK")+COUNTIF(Equipo!K68,"OK")+COUNTIF(Equipo!K75,"OK")+COUNTIF(Equipo!K76,"OK")+COUNTIF(Equipo!K77,"OK")+COUNTIF(Equipo!K78,"OK")+COUNTIF(Equipo!K85,"OK")+COUNTIF(Equipo!K86,"OK")+COUNTIF(Equipo!K87,"OK")+COUNTIF(Equipo!K88,"OK")+COUNTIF(Equipo!K89,"OK") -> 36 | C25: 36 | D25: =IF(B25=C25,"OK","ERROR") -> OK
A27: RESULTADO GENERAL | D27: =IF(COUNTIF(D4:D25,"OK")=22,"OK","ERROR") -> OK
