Workbook

Sheet Entregables Alto Nivel
A1: Entregables de alto nivel — Roadmap oficial del Caso de Negocio
A2: Fuente: Caso de Negocio Gestores - Mayo 2026, sección 6.2.1. Tabla oficial, sin modificar.
A4: Etapa | B4: Entregable | C4: Inicio | D4: Fin
A5: Estructuración | B5: Proyecto Negocio y TI | C5: may-26 | D5: jun-26
A6: Release 1 | B6: Gestor Solicitud | C6: jun-26 | D6: oct-26
A7: Release 1 | B7: Canales de acceso | C7: jun-26 | D7: oct-26
A8: Release 2 | B8: Gestor Evaluación | C8: oct-26 | D8: feb-27
A9: Release 2 | B9: Agente IA transcripción | C9: oct-26 | D9: feb-27
A10: Release 2 | B10: Agente IA pertinencia médica | C10: oct-26 | D10: feb-27
A11: Release 2 | B11: Gestor Coordinación | C11: oct-26 | D11: feb-27
A12: Release 3 | B12: Gestor Monitoreo | C12: feb-27 | D12: abr-27
A13: Release 3 | B13: Datalake autorizaciones | C13: feb-27 | D13: abr-27
A14: Estabilización | B14: Operación | C14: abr-27 | D14: may-27
A15: Cierre | B15: Proyecto | C15: may-27 | D15: jun-27
A17: Notas y supuestos
A18: • *La estimación inicial de fin del MVP (jun-27) está en revisión por parte de TI en tiempos y costos, según el propio Caso de Negocio.

Sheet Detalle
A1: ID | B1: Épica | C1: Equipo | D1: Release | E1: Talla | F1: Días | G1: Fecha inicio | H1: Fecha fin
A2: GST-001 | B2: Canales / Front Externos | C2: Frontend (Canales) | D2: Release 1 | E2: L | F2: 10 | G2: 46174 | H2: 46185
A3: GST-002 | B3: Canales / Front Externos | C3: Frontend (Canales) | D3: Release 1 | E3: L | F3: 10 | G3: 46174 | H3: 46185
A4: GST-003 | B4: Canales / Front Externos | C4: Frontend (Canales) | D4: Release 1 | E4: M | F4: 5 | G4: 46188 | H4: 46192
A5: GST-004 | B5: Canales / Front Externos | C5: Frontend (Canales) | D5: Release 1 | E5: M | F5: 5 | G5: 46188 | H5: 46192
A6: GST-005 | B6: Canales / Front Externos | C6: Frontend (Canales) | D6: Release 1 | E6: M | F6: 5 | G6: 46195 | H6: 46199
A7: GST-006 | B7: Gestor de Solicitud | C7: Backend Gestores | D7: Release 1 | E7: M | F7: 5 | G7: 46174 | H7: 46178
A8: GST-007 | B8: Gestor de Solicitud | C8: Backend Gestores | D8: Release 1 | E8: L | F8: 10 | G8: 46174 | H8: 46185
A9: GST-008 | B9: Gestor de Solicitud | C9: Backend Gestores | D9: Release 1 | E9: M | F9: 5 | G9: 46174 | H9: 46178
A10: GST-009 | B10: Gestor de Solicitud | C10: Backend Gestores | D10: Release 1 | E10: M | F10: 5 | G10: 46181 | H10: 46185
A11: GST-010 | B11: Gestor de Solicitud | C11: Backend Gestores | D11: Release 1 | E11: L | F11: 10 | G11: 46188 | H11: 46199
A12: GST-011 | B12: Gestor de Solicitud | C12: Backend Gestores | D12: Release 1 | E12: M | F12: 5 | G12: 46181 | H12: 46185
A13: GST-012 | B13: Gestor de Solicitud | C13: Backend Gestores | D13: Release 1 | E13: M | F13: 5 | G13: 46188 | H13: 46192
... A28: GST-027 | B28: Gestor de Evaluación | C28: Backend Gestores | D28: Release 2 | E28: L | F28: 10 | G28: 46345 | H28: 46358
A29: GST-028 | B29: Gestor de Asignación | C29: SuraHis (Core) | D29: Responsabilidad SuraHis (fuera del cronograma de Gestores) | E29: XL | F29: 20
A30: GST-029 | B30: Gestor de Asignación | C30: SuraHis (Core) | D30: Responsabilidad SuraHis (fuera del cronograma de Gestores) | E30: M | F30: 5
A31: GST-030 | B31: Gestor de Asignación | C31: SuraHis (Core) | D31: Responsabilidad SuraHis (fuera del cronograma de Gestores) | E31: M | F31: 5
A32: GST-031 | B32: Gestor de Asignación | C32: SuraHis (Core) | D32: Responsabilidad SuraHis (fuera del cronograma de Gestores) | E32: M | F32: 5
A33: GST-032 | B33: Gestor de Asignación | C33: SuraHis (Core) | D33: Responsabilidad SuraHis (fuera del cronograma de Gestores) | E33: L | F33: 10
A34: GST-033 | B34: Gestor de Asignación | C34: SuraHis (Core) | D34: Responsabilidad SuraHis (fuera del cronograma de Gestores) | E34: XL | F34: 20
A35: GST-034 | B35: Gestor de Coordinación | C35: Backend Gestores | D35: Release 2 | E35: L | F35: 10 | G35: 46296 | H35: 46309
A36: GST-035 | B36: Gestor de Coordinación | C36: Backend Gestores | D36: Release 2 | E36: L | F36: 10 | G36: 46296 | H36: 46309
A37: GST-036 | B37: Gestor de Coordinación | C37: Backend Gestores | D37: Release 2 | E37: XL | F37: 20 | G37: 46310 | H37: 46337
A38: GST-037 | B38: Gestor de Coordinación | C38: Backend Gestores | D38: Release 2 | E38: L | F38: 10 | G38: 46310 | H38: 46323
A39: GST-038 | B39: Gestor de Coordinación | C39: Backend Gestores | D39: Release 2 | E39: L | F39: 10 | G39: 46338 | H39: 46351
A40: GST-039 | B40: Gestor de Coordinación | C40: Backend Gestores | D40: Release 2 | E40: S | F40: 2 | G40: 46324 | H40: 46325
A41: GST-040 | B41: Gestor de Coordinación | C41: Backend Gestores | D41: Release 2 | E41: L | F41: 10 | G41: 46352 | H41: 46365
A42: GST-041 | B42: Gestor de Prestación | C42: Backend Gestores | D42: Pendiente de asignación de release | E42: XL | F42: 20
A43: GST-042 | B43: Gestor de Prestación | C43: Backend Gestores | D43: Pendiente de asignación de release | E43: L | F43: 10
A44: GST-043 | B44: Gestor de Prestación | C44: Backend Gestores | D44: Pendiente de asignación de release | E44: M | F44: 5
A45: GST-044 | B45: Gestor de Prestación | C45: Backend Gestores | D45: Pendiente de asignación de release | E45: M | F45: 5
A46: GST-045 | B46: Gestor de Monitoreo (Torre de Control) | C46: Backend Gestores | D46: Release 3 | E46: M | F46: 5 | G46: 46419 | H46: 46423
A47: GST-046 | B47: Gestor de Monitoreo (Torre de Control) | C47: Backend Gestores | D47: Release 3 | E47: M | F47: 5 | G47: 46419 | H47: 46423
A48: GST-047 | B48: Gestor de Monitoreo (Torre de Control) | C48: Backend Gestores | D48: Release 3 | E48: L | F48: 10 | G48: 46426 | H48: 46437
A49: GST-048 | B49: Gestor de Monitoreo (Torre de Control) | C49: Backend Gestores | D49: Release 3 | E49: L | F49: 10 | G49: 46426 | H49: 46437
A50: GST-049 | B50: Gestor de Monitoreo (Torre de Control) | C50: Backend Gestores | D50: Release 3 | E50: M | F50: 5 | G50: 46440 | H50: 46444
A51: GST-050 | B51: Gestor de Monitoreo (Torre de Control) | C51: Backend Gestores | D51: Release 3 | E51: M | F51: 5 | G51: 46440 | H51: 46444
A52: GST-051 | B52: Gestor de Monitoreo (Torre de Control) | C52: Backend Gestores | D52: Release 3 | E52: L | F52: 10 | G52: 46447 | H52: 46458
A53: GST-052 | B53: Gestor de Monitoreo (Torre de Control) | C53: Backend Gestores | D53: Release 3 | E53: L | F53: 10 | G53: 46447 | H53: 46458
A54: GST-053 | B54: Gestor de Monitoreo (Torre de Control) | C54: Backend Gestores | D54: Release 3 | E54: M | F54: 5 | G54: 46461 | H54: 46465
...

Sheet Cronograma por Frente
A1: Cronograma de releases — detalle por frente y equipo
A2: Agregado a partir de las 127 estimaciones por HU (ver archivo 3_Estimaciones_por_HU). Fechas y días recalculados con fórmulas sobre la hoja Detalle.
A4: Release | B4: Frente / Épica | C4: Equipo(s) involucrados | D4: # Entregables | E4: Días hábiles totales | F4: Días c/margen 30% | G4: Fecha inicio propuesta | H4: Fecha fin propuesta
A5: Release 1 | B5: Canales / Front Externos | C5: Frontend (Canales) | D5: =COUNTIFS(Detalle!$D:$D,$A5,Detalle!$B:$B,$B5) -> 10 | E5: =SUMIFS(Detalle!$F:$F,Detalle!$D:$D,$A5,Detalle!$B:$B,$B5) -> 105 | F5: =ROUNDUP(E5*(1+0.3),0) -> 137 | G5: =IF(COUNTIFS(Detalle!$G:$G,"<>",Detalle!$D:$D,$A5,Detalle!$B:$B,$B5)=0,"—",_xlfn.MINIFS(Detalle!$G:$G,Detalle!$D:$D,$A5,Detalle!$B:$B,$B5)) -> 46174 | H5: =IF(COUNTIFS(Detalle!$G:$G,"<>",Detalle!$D:$D,$A5,Detalle!$B:$B,$B5)=0,"—",_xlfn.MAXIFS(Detalle!$H:$H,Detalle!$D:$D,$A5,Detalle!$B:$B,$B5)) -> 46262
A6: Release 1 | B6: Gestor de Solicitud | C6: Arquitectura / DevOps, Backend Gestores | D6: =COUNTIFS(Detalle!$D:$D,$A6,Detalle!$B:$B,$B6) -> 22 | E6: =SUMIFS(Detalle!$F:$F,Detalle!$D:$D,$A6,Detalle!$B:$B,$B6) -> 195 | F6: =ROUNDUP(E6*(1+0.3),0) -> 254 | G6: =IF(COUNTIFS(Detalle!$G:$G,"<>",Detalle!$D:$D,$A6,Detalle!$B:$B,$B6)=0,"—",_xlfn.MINIFS(Detalle!$G:$G,Detalle!$D:$D,$A6,Detalle!$B:$B,$B6)) -> 46174 | H6: =IF(COUNTIFS(Detalle!$G:$G,"<>",Detalle!$D:$D,$A6,Detalle!$B:$B,$B6)=0,"—",_xlfn.MAXIFS(Detalle!$H:$H,Detalle!$D:$D,$A6,Detalle!$B:$B,$B6)) -> 46269
A7: Release 2 | B7: Gestor de Coordinación | C7: Arquitectura / DevOps, Backend Gestores | D7: =COUNTIFS(Detalle!$D:$D,$A7,Detalle!$B:$B,$B7) -> 14 | E7: =SUMIFS(Detalle!$F:$F,Detalle!$D:$D,$A7,Detalle!$B:$B,$B7) -> 142 | F7: =ROUNDUP(E7*(1+0.3),0) -> 185 | G7: =IF(COUNTIFS(Detalle!$G:$G,"<>",Detalle!$D:$D,$A7,Detalle!$B:$B,$B7)=0,"—",_xlfn.MINIFS(Detalle!$G:$G,Detalle!$D:$D,$A7,Detalle!$B:$B,$B7)) -> 46296 | H7: =IF(COUNTIFS(Detalle!$G:$G,"<>",Detalle!$D:$D,$A7,Detalle!$B:$B,$B7)=0,"—",_xlfn.MAXIFS(Detalle!$H:$H,Detalle!$D:$D,$A7,Detalle!$B:$B,$B7)) -> 46400
A8: Release 2 | B8: Gestor de Evaluación | C8: Arquitectura / DevOps, Backend Gestores | D8: =COUNTIFS(Detalle!$D:$D,$A8,Detalle!$B:$B,$B8) -> 15 | E8: =SUMIFS(Detalle!$F:$F,Detalle!$D:$D,$A8,Detalle!$B:$B,$B8) -> 140 | F8: =ROUNDUP(E8*(1+0.3),0) -> 182 | G8: =IF(COUNTIFS(Detalle!$G:$G,"<>",Detalle!$D:$D,$A8,Detalle!$B:$B,$B8)=0,"—",_xlfn.MINIFS(Detalle!$G:$G,Detalle!$D:$D,$A8,Detalle!$B:$B,$B8)) -> 46296 | H8: =IF(COUNTIFS(Detalle!$G:$G,"<>",Detalle!$D:$D,$A8,Detalle!$B:$B,$B8)=0,"—",_xlfn.MAXIFS(Detalle!$H:$H,Detalle!$D:$D,$A8,Detalle!$B:$B,$B8)) -> 46393
A9: Release 3 | B9: Gestor de Monitoreo (Torre de Control) | C9: Arquitectura / DevOps, Backend Gestores | D9: =COUNTIFS(Detalle!$D:$D,$A9,Detalle!$B:$B,$B9) -> 14 | E9: =SUMIFS(Detalle!$F:$F,Detalle!$D:$D,$A9,Detalle!$B:$B,$B9) -> 122 | F9: =ROUNDUP(E9*(1+0.3),0) -> 159 | G9: =IF(COUNTIFS(Detalle!$G:$G,"<>",Detalle!$D:$D,$A9,Detalle!$B:$B,$B9)=0,"—",_xlfn.MINIFS(Detalle!$G:$G,Detalle!$D:$D,$A9,Detalle!$B:$B,$B9)) -> 46419 | H9: =IF(COUNTIFS(Detalle!$G:$G,"<>",Detalle!$D:$D,$A9,Detalle!$B:$B,$B9)=0,"—",_xlfn.MAXIFS(Detalle!$H:$H,Detalle!$D:$D,$A9,Detalle!$B:$B,$B9)) -> 46518
A10: Paralelo (Release 1-3) | B10: AVA (Asesores) | C10: Integración AVA | D10: =COUNTIFS(Detalle!$D:$D,$A10,Detalle!$B:$B,$B10) -> 4 | E10: =SUMIFS(Detalle!$F:$F,Detalle!$D:$D,$A10,Detalle!$B:$B,$B10) -> 40 | F10: =ROUNDUP(E10*(1+0.3),0) -> 52 | G10: =IF(COUNTIFS(Detalle!$G:$G,"<>",Detalle!$D:$D,$A10,Detalle!$B:$B,$B10)=0,"—",_xlfn.MINIFS(Detalle!$G:$G,Detalle!$D:$D,$A10,Detalle!$B:$B,$B10)) -> 46143 | H10: =IF(COUNTIFS(Detalle!$G:$G,"<>",Detalle!$D:$D,$A10,Detalle!$B:$B,$B10)=0,"—",_xlfn.MAXIFS(Detalle!$H:$H,Detalle!$D:$D,$A10,Detalle!$B:$B,$B10)) -> 46198
A11: Paralelo (Release 1-3) | B11: Interoperabilidad (Prestadores) | C11: Backend Gestores, Interoperabilidad | D11: =COUNTIFS(Detalle!$D:$D,$A11,Detalle!$B:$B,$B11) -> 16 | E11: =SUMIFS(Detalle!$F:$F,Detalle!$D:$D,$A11,Detalle!$B:$B,$B11) -> 200 | F11: =ROUNDUP(E11*(1+0.3),0) -> 260 | G11: =IF(COUNTIFS(Detalle!$G:$G,"<>",Detalle!$D:$D,$A11,Detalle!$B:$B,$B11)=0,"—",_xlfn.MINIFS(Detalle!$G:$G,Detalle!$D:$D,$A11,Detalle!$B:$B,$B11)) -> 46143 | H11: =IF(COUNTIFS(Detalle!$G:$G,"<>",Detalle!$D:$D,$A11,Detalle!$B:$B,$B11)=0,"—",_xlfn.MAXIFS(Detalle!$H:$H,Detalle!$D:$D,$A11,Detalle!$B:$B,$B11)) -> 46422
A12: Paralelo (Release 1-2) | B12: NEXO (Asesores) | C12: Integración Nexo | D12: =COUNTIFS(Detalle!$D:$D,$A12,Detalle!$B:$B,$B12) -> 5 | E12: =SUMIFS(Detalle!$F:$F,Detalle!$D:$D,$A12,Detalle!$B:$B,$B12) -> 50 | F12: =ROUNDUP(E12*(1+0.3),0) -> 65 | G12: =IF(COUNTIFS(Detalle!$G:$G,"<>",Detalle!$D:$D,$A12,Detalle!$B:$B,$B12)=0,"—",_xlfn.MINIFS(Detalle!$G:$G,Detalle!$D:$D,$A12,Detalle!$B:$B,$B12)) -> 46143 | H12: =IF(COUNTIFS(Detalle!$G:$G,"<>",Detalle!$D:$D,$A12,Detalle!$B:$B,$B12)=0,"—",_xlfn.MAXIFS(Detalle!$H:$H,Detalle!$D:$D,$A12,Detalle!$B:$B,$B12)) -> 46212
A13: Transversal | B13: SuraHis (Core - dependencia) | C13: SuraHis (Core) | D13: =COUNTIFS(Detalle!$D:$D,$A13,Detalle!$B:$B,$B13) -> 1 | E13: =SUMIFS(Detalle!$F:$F,Detalle!$D:$D,$A13,Detalle!$B:$B,$B13) -> 10 | F13: =ROUNDUP(E13*(1+0.3),0) -> 13 | G13: =IF(COUNTIFS(Detalle!$G:$G,"<>",Detalle!$D:$D,$A13,Detalle!$B:$B,$B13)=0,"—",_xlfn.MINIFS(Detalle!$G:$G,Detalle!$D:$D,$A13,Detalle!$B:$B,$B13)) -> 46143 | H13: =IF(COUNTIFS(Detalle!$G:$G,"<>",Detalle!$D:$D,$A13,Detalle!$B:$B,$B13)=0,"—",_xlfn.MAXIFS(Detalle!$H:$H,Detalle!$D:$D,$A13,Detalle!$B:$B,$B13)) -> 46156
A14: Estructuración + Transversal | B14: Transversal / Arquitectura y Principios | C14: Arquitectura / DevOps, Backend Gestores | D14: =COUNTIFS(Detalle!$D:$D,$A14,Detalle!$B:$B,$B14) -> 12 | E14: =SUMIFS(Detalle!$F:$F,Detalle!$D:$D,$A14,Detalle!$B:$B,$B14) -> 122 | F14: =ROUNDUP(E14*(1+0.3),0) -> 159 | G14: =IF(COUNTIFS(Detalle!$G:$G,"<>",Detalle!$D:$D,$A14,Detalle!$B:$B,$B14)=0,"—",_xlfn.MINIFS(Detalle!$G:$G,Detalle!$D:$D,$A14,Detalle!$B:$B,$B14)) -> 46143 | H14: =IF(COUNTIFS(Detalle!$G:$G,"<>",Detalle!$D:$D,$A14,Detalle!$B:$B,$B14)=0,"—",_xlfn.MAXIFS(Detalle!$H:$H,Detalle!$D:$D,$A14,Detalle!$B:$B,$B14)) -> 46233
A15: Responsabilidad SuraHis (fuera del cronograma de Gestores) | B15: Gestor de Asignación | C15: SuraHis (Core) | D15: =COUNTIFS(Detalle!$D:$D,$A15,Detalle!$B:$B,$B15) -> 6 | E15: =SUMIFS(Detalle!$F:$F,Detalle!$D:$D,$A15,Detalle!$B:$B,$B15) -> 65 | F15: =ROUNDUP(E15*(1+0.3),0) -> 85 | G15: =IF(COUNTIFS(Detalle!$G:$G,"<>",Detalle!$D:$D,$A15,Detalle!$B:$B,$B15)=0,"—",_xlfn.MINIFS(Detalle!$G:$G,Detalle!$D:$D,$A15,Detalle!$B:$B,$B15)) -> — | H15: =IF(COUNTIFS(Detalle!$G:$G,"<>",Detalle!$D:$D,$A15,Detalle!$B:$B,$B15)=0,"—",_xlfn.MAXIFS(Detalle!$H:$H,Detalle!$D:$D,$A15,Detalle!$B:$B,$B15)) -> —
A16: Pendiente de asignación de release | B16: Gestor de Prestación | C16: Arquitectura / DevOps, Backend Gestores | D16: =COUNTIFS(Detalle!$D:$D,$A16,Detalle!$B:$B,$B16) -> 6 | E16: =SUMIFS(Detalle!$F:$F,Detalle!$D:$D,$A16,Detalle!$B:$B,$B16) -> 70 | F16: =ROUNDUP(E16*(1+0.3),0) -> 91 | G16: =IF(COUNTIFS(Detalle!$G:$G,"<>",Detalle!$D:$D,$A16,Detalle!$B:$B,$B16)=0,"—",_xlfn.MINIFS(Detalle!$G:$G,Detalle!$D:$D,$A16,Detalle!$B:$B,$B16)) -> — | H16: =IF(COUNTIFS(Detalle!$G:$G,"<>",Detalle!$D:$D,$A16,Detalle!$B:$B,$B16)=0,"—",_xlfn.MAXIFS(Detalle!$H:$H,Detalle!$D:$D,$A16,Detalle!$B:$B,$B16)) -> —
A17: Fuera de alcance MVP | B17: Gestor de Finalización | C17: Arquitectura / DevOps | D17: =COUNTIFS(Detalle!$D:$D,$A17,Detalle!$B:$B,$B17) -> 2 | E17: =SUMIFS(Detalle!$F:$F,Detalle!$D:$D,$A17,Detalle!$B:$B,$B17) -> 22 | F17: =ROUNDUP(E17*(1+0.3),0) -> 29 | G17: =IF(COUNTIFS(Detalle!$G:$G,"<>",Detalle!$D:$D,$A17,Detalle!$B:$B,$B17)=0,"—",_xlfn.MINIFS(Detalle!$G:$G,Detalle!$D:$D,$A17,Detalle!$B:$B,$B17)) -> — | H17: =IF(COUNTIFS(Detalle!$G:$G,"<>",Detalle!$D:$D,$A17,Detalle!$B:$B,$B17)=0,"—",_xlfn.MAXIFS(Detalle!$H:$H,Detalle!$D:$D,$A17,Detalle!$B:$B,$B17)) -> —
A19: Notas y supuestos
A20: • Filas con fecha '—' corresponden a frentes sin equipo propio asignado en el cronograma de Gestores (p. ej. Gestor de Asignación y SuraHis son responsabilidad del core, y Gestor de Prestación/Finalización aún no tienen arquitectura ni equipo asignado).
A21: • El detalle HU por HU (127 filas) está en el archivo '3_Estimaciones_por_HU_Gestores.xlsx'; este cronograma es su agregado por Release y Frente.

Sheet Vista Gantt (bloques)
A1: Vista Gantt de releases (bloques mensuales)
A2: Cada celda sombreada indica que ese release/frente tiene actividad estimada en ese mes, según la hoja 'Cronograma por Frente'.
A4: Release | B4: Entregable | C4: May-26 | D4: Jun-26 | E4: Jul-26 | F4: Aug-26 | G4: Sep-26 | H4: Oct-26 | I4: Nov-26 | J4: Dec-26 | K4: Jan-27 | L4: Feb-27 | M4: Mar-27 | N4: Apr-27 | O4: May-27 | P4: Jun-27
A5: Estructuración | B5: Proyecto Negocio y TI
A6: Release 1 | B6: Gestor de Solicitud + Canales de acceso
A7: Release 2 | B7: Gestor de Evaluación + Agente IA transcripción + Agente IA pertinencia médica + Gestor de Coordinación
A8: Release 3 | B8: Gestor de Monitoreo + Datalake de autorizaciones
A9: Estabilización | B9: Operación
A10: Cierre | B10: Cierre del proyecto
