Workbook

Sheet Léeme
B2: PROYECTO GESTORES — Ficha Integral de Iniciativa 2026
B3: Transformación del modelo operativo de Prestaciones y Reclamaciones · MVP Autorizaciones de Salud
B5: Qué cambió en esta versión | C5: Se incorporaron las definiciones de las sesiones del 18, 19 y 20 de agosto de 2026 (arranque de cronograma de releases, ejercicio de detalle funcional/técnico de Solicitud y Evaluación, y revisión técnica con Milton). Cada definición nueva se clasificó como requisito funcional (RF) o no funcional (RNF) y entró al plan y a la estimación. La columna 'Origen' permite distinguir lo que venía del archivo de requisitos v2 de lo nuevo.
B6: Sprint 0 — septiembre 2026 | C6: Antes de cualquier implementación hay un Sprint 0 que ocupa todo septiembre de 2026: configuración técnica, conformación y capacitación del equipo, transferencia de contexto funcional, y bases de infraestructura y arquitectura (catálogo de eventos, contratos de API, Runtime agéntico y Control Plane). No produce funcionalidad de negocio, pero sin él el Release 1 no arranca.
B7: Release 1 — octubre a diciembre 2026 | C7: El Sprint 1 inicia el 1 de octubre de 2026. La construcción del Release 1 ocupa los sprints 1 a 4 (octubre y noviembre, ~2 meses de trabajo efectivo) y el sprint 5 (7 al 22 de diciembre) queda reservado para estabilización, pruebas y entrega — no para alcance nuevo. El alcance está acotado, según el acuerdo de la sesión del 18-ago, a radicar una solicitud de autorización por un rol y un canal específicos: se excluyen modificaciones, reestudio, anulación, renovación, certificados, exterior, recién nacido e integralidad.
B8: Cómo se acotó el Release 1 | C8: El alcance no se recortó a ojo. Se filtraron los requisitos de Solicitud y Plataforma que pertenecen al camino de radicación, se ordenaron por prioridad MoSCoW y se fueron admitiendo hasta agotar un presupuesto de capacidad: 8 carriles (5 de Solicitud + 3 de Plataforma) x 33 días hábiles de construcción, con 20% de holgura = 211 días hábiles. Entraron 20 requisitos que suman 209 días. Todo lo que no cupo quedó marcado en el backlog como 'Diferido al Release 2 por capacidad del MVP de diciembre', para que la decisión sea visible y reversible.
B9: Por qué el Release 1 es Solicitud y no Evaluación | C9: El equipo confirmó que la dependencia entre gestores sigue el orden del flujo: sin la solicitud ningún otro gestor tiene insumo para operar. Evaluación es el gestor más complejo (pertinencia médica) y su propio mínimo viable tomaría cerca de cuatro meses, por lo que no es viable para diciembre. Solicitud tiene terreno ganado por la reutilización de Siniestro Integral, de un lector de IA existente y de los canales actuales.
B10: Calendario | C10: 100% hábil de Colombia: se excluyen sábados, domingos y los 18 festivos oficiales (incluida Semana Santa, calculados por año con la Ley Emiliani).
B11: Sprints | C11: Sprints de 11 días hábiles. Sprint 0 = todo septiembre de 2026. Sprint 1 = primer día hábil de octubre de 2026.
B12: Escala de talla | C12: XXL = 30 días hábiles (3+ sprints) · XL = 20 días (2 sprints) · L = 10 días (1 sprint) · M = 5 días (medio sprint) · S = 3 días (un cuarto de sprint) · XS = 1 día.
B13: Cómo se asignó la talla | C13: Heurística por palabras clave (arquitectura, motor, IA, integración, catálogo, etc.) más longitud del texto del requisito. Es una primera pasada reproducible, no un tallaje de equipo. La sesión del 18-ago dejó explícito que estas estimaciones preliminares están sujetas a sesgo y deben validarse con el equipo técnico; el ejercicio de dimensionamiento de agentes con el driver de NTT Data es el mecanismo acordado para hacerlo.
B14: Cómo se calcularon las fechas | C14: Cada squad tiene un número de carriles paralelos (aprox. su número de desarrolladores). Los requisitos de cada combinación squad + release se reparten entre esos carriles y cada carril avanza de forma continua según la duración de talla. Ver hoja 'Equipos y Paralelización'.
B15: Celdas en ámbar y verde | C15: Ámbar = dato PENDIENTE POR CONFIRMAR, no completado con supuestos. Verde = definición nueva proveniente de las sesiones del 18 al 20 de agosto de 2026.
B16: Advertencia de contexto | C16: La contingencia del terremoto generó atraso: al 20-ago el avance de estructuración era del 49% frente a un 68% esperado. Estas fechas asumen que el equipo técnico puede arrancar el Sprint 0 el 1 de septiembre.
B18: Ventanas de release (calculadas a partir de la programación real)
B19: Release | C19: Fecha inicio | D19: Fecha fin | E19: Sprints
B20: Sprint 0 | C20: 01-Sep-2026 | D20: 28-Sep-2026 | E20: S0–S0
B21: Release 1 | C21: 01-Oct-2026 | D21: 30-Nov-2026 | E21: S1–S4
B22: Release 2 | C22: 12-Jan-2027 | D22: 08-Jun-2027 | E22: S7–S16
B23: Release 3 | C23: 20-May-2027 | D23: 24-Sep-2027 | E23: S15–S22
B24: Fase posterior | C24: 13-Sep-2027 | D24: 31-Dec-2027 | E24: S22–S28
B27: Elaborado por | C27: Equipo de Estructuración — Proyecto Gestores · Agosto 2026

Sheet Definición-ImpactMap
A1: PLAN DE RELEASES E IMPACT MAP ¿Porqué construimos esto y a quién impacta?
A2: Cada fila es un requisito funcional (RF) o no funcional (RNF) convertido en actividad de release, con su gestor, talla y sprint estimado. Incluye los requisitos del archivo v2 y las definiciones nuevas de las sesiones del 18 al 20 de agosto (columna Origen, resaltada en verde). El Mapa de Actores lista los aplicativos impactados por el Release 1, según instrucción de la plantilla.
A4: PLAN DE RELEASES | L4: MAPA DE ACTORES (solo Release 1)
A5: Release | B5: Gestor(es) asociado(s) | C5: Tipo | D5: Origen | E5: Actividad o Proceso (requisito) | F5: Entregable / Decisión de seguimiento | G5: Categoría de priorización | H5: Talla | I5: Sprint(s) estimado(s) | J5: Observaciones (duda / estado de origen) | L5: Aplicativo | M5: Dominio | N5: Líder TI | O5: Responsable de negocio (APM) | P5: Observaciones
A6: Sprint 0 | B6: Canales / Front Externos | C6: RNF | D6: Sprint 0 (definido 18–20 ago) | E6: Confirmación del alcance del Release 1 con negocio y con el equipo de canales: rol y canal específicos, y compatibilidad de cronogramas. | F6: Por definir en el taller de estimación | G6: Debe tener | H6: M | I6: Sprint 0 | J6: Estado de origen: Sprint 0 — Preparación · Nota: James no había entregado su estimación de esfuerzo al 18-ago. | L6: Sucursal Virtual Prestador de salud y Proveedor de asistencia | M6: Transformación Digital | N6: Juan Carlos Betancur Piedrahita | O6: Lucrecia Andrea Lenis Tangarife; Manuela Molina Ospina | P6: Canal principal del prestador (70–80% del volumen)
A7: Sprint 0 | B7: Transversal / Principios generales | C7: RNF | D7: Sprint 0 (definido 18–20 ago) | E7: Conformación y onboarding del equipo: definición de squads, roles y dedicaciones, y capacitación del personal nuevo en el dominio de autorizaciones de salud. | F7: Riesgo señalado en la sesión del 18-ago | G7: Debe tener | H7: M | I7: Sprint 0 | J7: Estado de origen: Sprint 0 — Preparación · Nota: Armar y capacitar un equipo nuevo puede tomar más de la mitad de septiembre. | L7: Sucursal virtual prestadores (En Desarrollo) | M7: PENDIENTE POR CONFIRMAR | N7: PENDIENTE POR CONFIRMAR | O7: PENDIENTE POR CONFIRMAR | P7: Nuevo portal en construcción; confirmar registro APM
A8: Sprint 0 | B8: Transversal / Principios generales | C8: RNF | D8: Sprint 0 (definido 18–20 ago) | E8: Habilitación de ambientes de desarrollo y pruebas, infraestructura base, repositorios, pipelines de CI/CD y estándares de código. | F8: Por definir en el taller de estimación | G8: Debe tener | H8: M | I8: Sprint 0 | J8: Estado de origen: Sprint 0 — Preparación | L8: Sucursal Virtual Personas | M8: Transformación Digital | N8: Juan Carlos Betancur Piedrahita | O8: Laura Mejía Arango | P8: Front nuevo en Flutter embebido; salida del embebido de ADR
A9: Sprint 0 | B9: Transversal / Principios generales | C9: RNF | D9: Sprint 0 (definido 18–20 ago) | E9: Configuración del Runtime agéntico y del Control Plane corporativo (gateway de consumo de LLM y gestión de prompts) para el equipo de Gestores. | F9: Por definir en el taller de estimación | G9: Debe tener | H9: L | I9: Sprint 0 | J9: Estado de origen: Sprint 0 — Preparación · Nota: Depende del avance de la plataforma agéntica corporativa que construye el equipo de IA. | L9: SuperAPP | M9: Plataforma Digital SURA | N9: Sergio Andrés Pérez Pérez | O9: Erika Andrea Solórzano López | P9: Riesgo técnico abierto: Super App en Google Cloud vs. resto del ecosistema en Azure
A10: Sprint 0 | B10: Transversal / Principios generales | C10: RNF | D10: Sprint 0 (definido 18–20 ago) | E10: Elaboración del borrador del catálogo de eventos y de los contratos de API que servirán de base al Release 1. | F10: Camino crítico: sin este contrato ningún squad puede construir | G10: Debe tener | H10: L | I10: Sprint 0 | J10: Estado de origen: Sprint 0 — Preparación | L10: ADR | M10: Aseguramiento | N10: Alexis De Jesús Ramos Behaine | O10: Camilo Andrés Muñoz Uribe; Carolina Villegas Londoño | P10: Uno de los cuatro sistemas que hoy usa el evaluador en paralelo
A11: Sprint 0 | B11: Transversal / Principios generales | C11: RNF | D11: Sprint 0 (definido 18–20 ago) | E11: Acuerdo formal de capacidad y disponibilidad con el equipo de SuraHis para la exposición de APIs y eventos del core. | F11: Requiere compromiso explícito con Andrés Charry | G11: Debe tener | H11: L | I11: Sprint 0 | J11: Estado de origen: Sprint 0 — Preparación · Nota: Dependencia crítica número uno del proyecto. | L11: Globalweb | M11: Aseguramiento | N11: Alexis De Jesús Ramos Behaine; Germán Darío Tamayo Zuluaga | O11: Sandra Liliana Aristizábal Escobar | P11: Se decide comprobar derechos vía SuraHis y no vía Global Web
A12: Sprint 0 | B12: Transversal / Principios generales | C12: RNF | D12: Sprint 0 (definido 18–20 ago) | E12: Transferencia de contexto funcional al equipo técnico: proceso actual de autorizaciones, modelo de estados, entidades y decisiones de arquitectura ya tomadas. | F12: Por definir en el taller de estimación | G12: Debe tener | H12: L | I12: Sprint 0 | J12: Estado de origen: Sprint 0 — Preparación | L12: Siniestro integral | M12: Aseguramiento | N12: Alexis De Jesús Ramos Behaine | O12: osiris Acevedo Blanco | P12: Base reutilizada (front, back, API Gateway, orquestador, storage)
A13: Sprint 0 | B13: Transversal / Principios generales | C13: RNF | D13: Sprint 0 (definido 18–20 ago) | E13: Cierre del ejercicio de dimensionamiento de agentes y estimación de costo, aplicando el driver construido con NTT Data. | F13: Ejercicio iniciado el 21-ago de 1:30 p.m. a 5:00 p.m. | G13: Debe tener | H13: M | I13: Sprint 0 | J13: Estado de origen: Sprint 0 — Preparación · Nota: El driver estaba en borrador al 20-ago. | L13: Apigee | M13: Plataforma Digital SURA | N13: Sergio Andrés Pérez Pérez | O13: Carlos David Arango Castaño | P13: Exposición API First y MCP hacia canales, aliados y agentes
A14: Sprint 0 | B14: Transversal / Principios generales | C14: RNF | D14: Sprint 0 (definido 18–20 ago) | E14: Definición del umbral de asertividad y de las métricas de calidad de los agentes que se aplicarán desde el Release 1. | F14: Por definir en el taller de estimación | G14: Debe tener | H14: M | I14: Sprint 0 | J14: Estado de origen: Sprint 0 — Preparación · Nota: Valor exacto del umbral por definir. | L14: HIS Administrativo Salud (SuraHis) | M14: Prestación / Distribución | N14: Andrés Felipe Charry Correa | O14: Paula Andrea Peña Sierra | P14: Dependencia crítica: fuente de verdad transaccional, no motor de reglas
A15: Sprint 0 | B15: Transversal / Principios generales | C15: RNF | D15: Sprint 0 (definido 18–20 ago) | E15: Validación con el equipo técnico de los tallajes y estimaciones preliminares, y ajuste del backlog del Release 1 antes de iniciar la implementación. | F15: Por definir en el taller de estimación | G15: Debe tener | H15: M | I15: Sprint 0 | J15: Estado de origen: Sprint 0 — Preparación | L15: P8 (Archivo Digital) | M15: Servicios de infraestructura de TI | N15: José Alejandro Betancur Mejía; Daniel Stiven Ruiz Díaz | O15: Daniel Stiven Ruiz Díaz | P15: Dependencia crítica para custodia documental; PoC con Oracle como alternativa
A16: Sprint 0 | B16: Gestor de Solicitud | C16: RNF | D16: Sprint 0 (definido 18–20 ago) | E16: Decisión técnica del lector de IA a reutilizar (ADR vs. desarrollo de TT) y prueba de concepto de la extracción documental sobre documentos reales. | F16: Por definir en el taller de estimación | G16: Debe tener | H16: L | I16: Sprint 0 | J16: Estado de origen: Sprint 0 — Preparación · Nota: Impactada por el recorte de presupuesto del equipo de salud modular. | L16: Notificaciones | M16: Soluciones Corporativas | N16: Daniel Stiven Ruiz Díaz | O16: Daniel Stiven Ruiz Díaz | P16: Notificación proactiva basada en eventos
... A22: Release 1 | B22: Transversal / Principios generales | C22: RNF | D22: Sesión 18-ago | E22: Confirmar el orden de dependencia entre gestores: cada gestor requiere el evento o salida del anterior, por lo que el Gestor de Solicitud es el punto de partida obligado del flujo. | F22: Sin la solicitud ningún otro gestor tiene insumo para operar | G22: Debe tener | H22: L | I22: S3–S4 | J22: Estado de origen: Nuevo — Definido en sesión 18-ago | L22: KONECTA (contact center) | M22: Actor externo — no aplicativo APM | N22: PENDIENTE POR CONFIRMAR | O22: PENDIENTE POR CONFIRMAR | P22: Link de gestión con hallazgos de seguridad; impacto contractual por reducción de preradicación
A23: Release 1 | B23: Gestor de Solicitud | C23: RF | D23: Requisitos v2 (12-ago) | E23: Documento no legible nunca bloquea al usuario: siempre pasa a bandeja de revisión manual. | F23: Por definir en el taller de estimación | G23: Debe tener | H23: M | I23: S1 | J23: Estado de origen: Definido
A24: Release 1 | B24: Siniestro Integral | C24: RF | D24: Requisitos v2 (12-ago) | E24: Modelo de datos "padre-hijo": la solicitud es el padre; cada autorización por servicio/CUPS es un hijo con estado propio. | F24: Por definir en el taller de estimación | G24: Debe tener | H24: M | I24: S1 | J24: Estado de origen: Definido
A25: Release 1 | B25: Gestor de Solicitud | C25: RF | D25: Requisitos v2 (12-ago) | E25: Extrae mediante agente IA la información de los documentos adjuntos (orden médica + historia clínica). | F25: Por definir en el taller de estimación | G25: Debe tener | H25: L | I25: S1 | J25: Estado de origen: Definido
A26: Release 1 | B26: Siniestro Integral | C26: RF | D26: Requisitos v2 (12-ago) | E26: Genera un ID temporal como número radicador (correlation ID), y almacena la información de forma temporal. | F26: Por definir en el taller de estimación | G26: Debe tener | H26: S | I26: S1 | J26: Estado de origen: Definido
A27: Release 1 | B27: Siniestro Integral | C27: RF | D27: Requisitos v2 (12-ago) | E27: Lleva los documentos a P8. | F27: Por definir en el taller de estimación | G27: Debe tener | H27: XS | I27: S1 | J27: Estado de origen: Definido
A28: Release 1 | B28: Siniestro Integral | C28: RF | D28: Requisitos v2 (12-ago) | E28: Publica el evento que activa al core de salud (SuraHis) para la generación de la solicitud; ese mismo evento alimenta el flujo de solicitud/autorización para la Torre de Control. | F28: Por definir en el taller de estimación | G28: Debe tener | H28: M | I28: S1 | J28: Estado de origen: Definido
A29: Release 1 | B29: Gestor de Solicitud | C29: RF | D29: Requisitos v2 (12-ago) | E29: Si la IA no identifica el documento con certeza, el caso va a bandeja manual sin notificar al asegurado que el documento es inválido (evita falsos negativos); solo se notifica si hay certeza de que el documento no corresponde. | F29: Por definir en el taller de estimación | G29: Debe tener | H29: XXL | I29: S1–S3 | J29: Estado de origen: Definido en sesión 10-ago
A30: Release 1 | B30: Gestor de Solicitud | C30: RF | D30: Requisitos v2 (12-ago) | E30: La bandeja de solicitud incompleta tiene bloqueo por exclusión mutua (mutex) mientras un analista/agente la trabaja, y un tiempo de vida (TTL) tras el cual se libera y puede escalarse. | F30: Por validar con negocio (ver hoja de Pendientes y Conversaciones) | G30: Debe tener | H30: L | I30: S1–S2 | J30: Estado de origen: Nuevo — Definido en sesión técnica 12-ago · Nota: Falta definir con negocio el valor exacto del TTL y el criterio de escalamiento por tipo de caso.
A31: Release 1 | B31: Gestor de Solicitud | C31: RNF | D31: Requisitos v2 (12-ago) | E31: Front nuevo (Flutter), embebido en Sucursal Virtual Personas, AVA y Portal de Prestadores; reutiliza el back/orquestador de Siniestro Integral. | F31: Por definir en el taller de estimación | G31: Debe tener | H31: M | I31: S1 | J31: Estado de origen: Definido
A32: Release 1 | B32: Gestor de Solicitud | C32: RNF | D32: Requisitos v2 (12-ago) | E32: Comprobación de derechos vía API de SuraHis (no Global Web) — mayor resiliencia y flexibilidad ante cambios futuros de core. | F32: Por definir en el taller de estimación | G32: Debe tener | H32: M | I32: S1 | J32: Estado de origen: Definido
A33: Release 1 | B33: Gestor de Solicitud | C33: RNF | D33: Requisitos v2 (12-ago) | E33: OCR/IA: LLM multimodal interpreta documentos directamente (15-40 seg); reutiliza el agente de pre-radicación de EPS (~93% de precisión). | F33: Por definir en el taller de estimación | G33: Debe tener | H33: L | I33: S1–S2 | J33: Estado de origen: Definido
A34: Release 1 | B34: Gestor de Solicitud | C34: RNF | D34: Requisitos v2 (12-ago) | E34: Arquitectura orientada a eventos: quien tiene autoridad sobre la entidad (normalmente SuraHis) es quien emite el evento. | F34: Por definir en el taller de estimación | G34: Debe tener | H34: XL | I34: S1–S3 | J34: Estado de origen: Definido
... A183: Fase posterior | B183: Gestor de Prestación | C183: RNF | D183: Requisitos v2 (12-ago) | E183: Integración con la cola de eventos de interoperabilidad de historia clínica (arquitectura 2.0) para conocer si el servicio autorizado fue efectivamente atendido, sin construir un componente tecnológico nuevo en Gestores. | F183: Por definir en el taller de estimación | G183: No debería | H183: XXL | I183: S26–S28 | J183: Estado de origen: Nuevo — Definido en sesión de Interoperabilidad 11-ago
A185: Leyenda | D185: Talla:
A186: Sprint 0 · sep-2026 (preparación) | D186: XS · 1 día
A187: Release 1 · oct–dic 2026 | D187: S · 3 días · 1/4 sprint
A188: Release 2 | D188: M · 5 días · 1/2 sprint
A189: Release 3 | D189: L · 10 días · 1 sprint
A190: Fase posterior / fuera de MVP | D190: XL · 20 días · 2 sprints
A191: Pendiente por confirmar | D191: XXL · 30 días · 3+ sprints

Sheet Estimación-Visual Story Map
A1: FASE DE ESTIMACIÓN · VISUAL STORY MAP — ¿Qué entra en cada release?
A2: Épicas = squads (gestores agrupados). Cada 'feature' agrupa hasta 6 requisitos en el orden del archivo fuente. El color de cada celda indica el release; el código entre corchetes es la talla del requisito.
A4: ÉPICAS | C4: Plataforma (Sprint 0) | I4: Solicitud (Sprint 0) | Q4: Canales (Sprint 0) | U4: Evaluación (Release 2) | AA4: Coordinación (Release 3) | AF4: Torre de Control (Release 3) | AL4: Prestación (Fase posterior) | AO4: Finalización (Fase posterior)
A5: FEATURES | C5: Bloque 1 Conformación y onboarding del… | D5: Bloque 2 Cierre del ejercicio de… | E5: Bloque 3 Riesgo/premisa explícita: el proyecto… | F5: Bloque 4 La interoperabilidad de historia… | G5: Bloque 5 Versionamiento de sistemas agénticos,… | I5: Bloque 1 Decisión técnica del lector… | J5: Bloque 2 Publica el evento que… | K5: Bloque 3 Arquitectura orientada a eventos:… | L5: Bloque 4 Se incorpora como requisito… | M5: Bloque 5 Modelo de datos de… | N5: Bloque 6 Modelo asíncrono de bandeja… | O5: Bloque 7 Umbral de asertividad: cada… | Q5: Bloque 1 Confirmación del alcance del… | R5: Bloque 2 Selección de prestador: el… | S5: Bloque 3 'Solicitar estado de cuenta'… | U5: Bloque 1 Consulta al Core (SuraHis)… | V5: Bloque 2 No genera el número… | W5: Bloque 3 Principio de diseño: la… | X5: Bloque 4 Evaluación estructurada en dos… | Y5: Bloque 5 La solicitud de autorización… | AA5: Bloque 1 La asignación al equipo… | AB5: Bloque 2 La notificación al cliente… | AC5: Bloque 3 Notifica tanto al asegurado… | AD5: Bloque 4 Integración con prestadores externos… | AF5: Bloque 1 Renombrado de "Monitoreo" a… | AG5: Bloque 2 Rescate digital automático: si… | AH5: Bloque 3 Arquitectura orientada a eventos… | AI5: Bloque 4 Controlar los niveles de… | AJ5: Bloque 5 El Data Lake es… | AL5: Bloque 1 Da seguimiento al "momento… | AM5: Bloque 2 Integración con clave dinámica… | AO5: Bloque 1 Es el gestor menos… | AP5: Bloque 2 Excluye explícitamente las "reglas…
A6: Req. 1 | C6: [M] Conformación y onboarding del equipo: definición de squads, roles y dedicaciones, y capacitació… | D6: [M] Cierre del ejercicio de dimensionamiento de agentes y estimación de costo, aplicando el driver … | E6: [M] Riesgo/premisa explícita: el proyecto solo tiene sentido si los cores implementan la capacidad … | F6: [XXL] La interoperabilidad de historia clínica ya cuenta con una arquitectura 2.0 orientada a eventos… | G6: [L] Versionamiento de sistemas agénticos, incluyendo la definición de si la data de reglas del core… | I6: [L] Decisión técnica del lector de IA a reutilizar (ADR vs. desarrollo de TT) y prueba de concepto … | J6: [M] Publica el evento que activa al core de salud (SuraHis) para la generación de la solicitud; ese… | K6: [XL] Arquitectura orientada a eventos: quien tiene autoridad sobre la entidad (normalmente SuraHis) … | L6: [S] Se incorpora como requisito funcional el "rescate de la solicitud" cuando la radicación no se c… | M6: [XL] Modelo de datos de la bandeja de solicitud: entidad flexible con campos por defecto 'desconocid… | N6: [XL] Modelo asíncrono de bandeja de solicitudes (recibida / notificación cuando requiere atención) e… | O6: [M] Umbral de asertividad: cada campo extraído viene con un porcentaje de confianza. Solo por encim… | Q6: [M] Confirmación del alcance del Release 1 con negocio y con el equipo de canales: rol y canal espe… | R6: [S] Selección de prestador: el campo queda como opcional y se traslada a un paso posterior del fluj… | S6: [L] 'Solicitar estado de cuenta' se renombra de cara al usuario (los asegurados lo conocen como 'ce… | U6: [M] Consulta al Core (SuraHis) coberturas, vigencias, convenios y exclusiones para los controles de… | V6: [M] No genera el número de solicitud de autorización/negación: deja el caso listo vía evento — el c… | W6: [L] Principio de diseño: la negación siempre debe ser determinística y trazable — nunca una decisió… | X6: [XXL] Evaluación estructurada en dos llamados al core en paralelo: reglas duras (producto, diagnóstic… | Y6: [M] La solicitud de autorización se desglosa en autorizaciones asociadas a un solo servicio, no a n… | AA6: [L] La asignación al equipo se distribuye según reglas de criticidad (marcas en salud, PEP, edad de… | AB6: [M] La notificación al cliente por incumplimiento de SLA se dispara vía evento publicado por la Tor… | AC6: [S] Notifica tanto al asegurado (prestador asignado) como al prestador (autorización pendiente de a… | AD6: [L] Integración con prestadores externos preferiblemente vía API con retroalimentación de estados. | AF6: [XS] Renombrado de "Monitoreo" a "Torre de Control" por ampliación de alcance durante las sesiones. | AG6: [L] Rescate digital automático: si falla el canal al radicar, contacta por WhatsApp/app para contin… | AH6: [XL] Arquitectura orientada a eventos (EDA): consume eventos de todos los gestores y cores, incluida… | AI6: [XS] Controlar los niveles de autonomía de los gestores agénticos. | AJ6: [M] El Data Lake es una fuente más de información para la Torre de Control (solo lectura, no consum… | AL6: [M] Da seguimiento al "momento de verdad": si la cita fue programada, si el paciente asistió, noved… | AM6: [XL] Integración con clave dinámica (doble factor) como mecanismo de confirmación de la atención efe… | AO6: [S] Es el gestor menos desarrollado de los 6 — solo definición conceptual, sin sesión de estructura… | AP6: [M] Excluye explícitamente las "reglas de pago automático" (corresponden a Cuentas Médicas, fuera d…
A7: Req. 2 | C7: [M] Habilitación de ambientes de desarrollo y pruebas, infraestructura base, repositorios, pipeline… | D7: [M] Definición del umbral de asertividad y de las métricas de calidad de los agentes que se aplicar… | E7: [XL] Se reutiliza la arquitectura de "Siniestro Integral" (Front + Back, API Gateway, orquestador, s… | F7: [M] Adoptar la metodología de estimar por cada gestor un escenario mínimo viable y uno completo/des… | G7: [L] Concepto de 'function fitness': pruebas equivalentes a las de desarrollo de software aplicadas … | I7: [M] Documento no legible nunca bloquea al usuario: siempre pasa a bandeja de revisión manual. | J7: [XXL] Si la IA no identifica el documento con certeza, el caso va a bandeja manual sin notificar al a… | K7: [S] Recibe solicitudes de 3 públicos: prestador (70-80% del volumen, foco prioritario), cliente/ase… | L7: [S] Modelo de 'solicitud laxa': la solicitud se crea con campos comodín (valores 'desconocido') que… | M7: [M] Alcance acotado del primer entregable de diciembre: radicar una solicitud de autorización para … | N7: [S] Alertar al asegurado cuando el documento cargado no corresponde a lo esperado, sin afectar su e… | O7: [S] Mecanismo de muestreo humano sobre los casos que el agente resuelve correctamente, no solo sobr… | Q7: [M] Comprobación de derechos (vigencia de póliza, mora) obligatoria al inicio del flujo, antes de p… | R7: [M] Reestudio: aplica solo cuando la autorización fue negada y el asegurado no está de acuerdo; el … | S7: [M] Reutilizar los canales existentes hoy para el primer release, coordinando en paralelo la estima… | U7: [M] Valida la pertinencia médica; decide autorizar, negar o escalar a evaluación manual (coherencia… | V7: [XL] Reutiliza el homologador de CUPS y el motor ya productivo del proyecto de autorizaciones EPS, e… | W7: [M] Hoy el evaluador humano usa 4 sistemas en paralelo (ADP, Global Web, ADR, P8) — meta explícita:… | X7: [L] La bandeja de 'listo para coordinación' tras una evaluación exitosa es la misma bandeja de 'pag… | Y7: [L] Si un servicio no se puede autorizar por la póliza voluntaria, esa solicitud hijo se niega y se… | AA7: [M] Para solicitudes pendientes por gestión se habilita la reasignación entre niveles. | AB7: [M] Direcciona el servicio ya autorizado al prestador adecuado: simple (un solo prestador posible, … | AC7: [S] Objetivo estratégico: mapear automáticamente la autorización contra el convenio/tarifa para pag… | AD7: [XL] Bandeja "human in the loop" para casos donde ni las reglas ni la recomendación logran asignar u… | AF7: [S] Monitorea el ciclo de vida completo de la autorización: cumplimiento de SLA/ANS, carga de traba… | AG7: [S] Detecta solicitudes repetidas (2 o más veces) con las mismas características y activa el mismo … | AH7: [M] El almacenamiento de eventos vive en un bus/componente dedicado, no exclusivo de este gestor — … | AI7: [M] Entregar información a distintos canales en el lenguaje requerido por cada actor, registrando c… | AJ7: [XL] Arquitectura tipo Lambda: vía rápida de eventos en tiempo real más vía lenta de productos del D… | AL7: [M] Mecanismo actual: confirmación por QR escaneado por el asegurado (piloto ya finalizado, solo co… | AM7: [L] Sin arquitectura técnica profundizada — reconocido explícitamente por el equipo de arquitectura… | AO7: [S] 3 pilares: satisfacción del cliente · conciliación y pago a proveedor (cuentas médicas) · pagos… | AP7: [L] Sin arquitectura ni componentes técnicos definidos en ninguna de las fuentes revisadas a la fec…
A8: Req. 3 | C8: [L] Configuración del Runtime agéntico y del Control Plane corporativo (gateway de consumo de LLM y… | D8: [M] Validación con el equipo técnico de los tallajes y estimaciones preliminares, y ajuste del back… | E8: [M] Se privilegia un front único reutilizable por canal/actor, en lugar de un front independiente p… | F8: [XL] Plataforma agéntica corporativa en construcción con el equipo de IA: Runtime agéntico (donde co… | G8: [M] Driver de dimensionamiento de agentes: parametrizar la complejidad de cada agente para aproxima… | I8: [M] Modelo de datos "padre-hijo": la solicitud es el padre; cada autorización por servicio/CUPS es … | J8: [L] La bandeja de solicitud incompleta tiene bloqueo por exclusión mutua (mutex) mientras un analis… | K8: [S] Meta: pedir solo identificación (aplica solo para prestador y asesor) + 2 documentos (historia … | L8: [L] Flujo: Front → Storage temporal de documentos → integración asíncrona con P8; PoC en curso con … | M8: [XL] Reutilizar el componente de Siniestro Integral a nivel de back para el primer release, en lugar… | N8: [M] Capa de agentes expertos: un agente por tipo de documento (historia clínica, orden médica, fact… | O8: [M] Límite de auto-reparación de prompts del agente auditor: no puede ser totalmente autónomo sin a… | Q8: [L] Documentos aparentemente inválidos no permiten continuar con la creación de la solicitud (agent… | R8: [M] Notificación y visibilidad cruzada cliente-prestador: se notifica al cliente cuando un prestado… | U8: [S] Regla crítica: la negación nunca se hace 100% automática — toda negación exige intervención de … | V8: [XL] Valida duplicidad (mismo prestador/documentos o mismo tipo de servicio) consultando histórico e… | W8: [M] Es, junto con Solicitud, el gestor con mayor avance de diseño a la fecha del último seguimiento… | X8: [M] Auditoría de decisiones automáticas: detectar desviaciones estadísticas y realizar revisión man… | AA8: [S] Cada solicitud debe tener un tiempo de respuesta asignado (100% de las solicitudes en menos de … | AB8: [M] 3 casos de negocio: producto modular (direccionamiento automático) · clásica/global (cliente el… | AC8: [L] Para el Release 1, la asignación interna de casos a evaluadores/niveles la resuelve SuraHis; el… | AD8: [M] Es uno de los gestores menos profundizados técnicamente a la fecha — "no se ha hecho zoom" toda… | AF8: [S] Regla explícita: no se monitorea todo lo que llega, solo lo que "se sale de lo esperado" — la c… | AG8: [M] Notificaciones basadas en eventos: el Core informa tiempos por etapa, la Torre de Control detec… | AH8: [L] Pendiente definir si se expone una API única con filtrado por perfil o múltiples APIs por actor… | AI8: [S] Detección de anomalías y fraude como capacidad agéntica, aprovechando la vista panorámica que e… | AJ8: [M] La capa de ingesta y consolidación debe tener capacidad de streaming, no procesamiento por lote… | AL8: [L] Se evalúa evolucionar a clave dinámica (doble factor, ya disponible en la app) como mecanismo d… | AM8: [XXL] Integración con la cola de eventos de interoperabilidad de historia clínica (arquitectura 2.0) … | AO8: [M] Equivale, en autorizaciones, al pago de la cuenta médica: el prestador carga la factura con det… | AP8: [XL] El Gestor de Finalización se representa en la arquitectura con líneas punteadas: no se implemen…
A9: Req. 4 | C9: [L] Elaboración del borrador del catálogo de eventos y de los contratos de API que servirán de base… | D9: [XL] Arquitectura de microservicios, agéntica, dirigida por eventos (EDA), moderna y desacoplada — s… | E9: [M] Diferenciación explícita comando (síncrono, se consume y desaparece) vs. evento (inmutable, usa… | F9: [L] Distinguir eventos funcionales (de las entidades de negocio, emitidos por su dueño) de eventos … | I9: [L] Extrae mediante agente IA la información de los documentos adjuntos (orden médica + historia cl… | J9: [M] Front nuevo (Flutter), embebido en Sucursal Virtual Personas, AVA y Portal de Prestadores; reut… | K9: [M] Autorización automática (algunas no requieren soportes) en servicios clasificados como "nivel 1… | L9: [L] Integración con NEXO vía API (patrón API First) + exposición como MCP para agentes conversacion… | M9: [XL] Reutilizar un lector de IA existente para la extracción documental: definir si se usa el de ADR… | N9: [M] Capa de salida configurable: arma el resultado final según lo que cada core consumidor necesite… | O9: [M] Agente juez que valide en tiempo real usando un modelo distinto al del agente evaluado, para qu… | Q9: [S] Omnicanalidad real: el historial de solicitudes/autorizaciones debe verse igual sin importar el… | R9: [S] Anulación de solicitudes: solo la puede hacer el prestador, y solo si el estado es 'en proceso'… | U9: [L] Revisar la integración para consultar mora (ir directamente al core de PDN o pasar por SuraHis)… | V9: [M] Consume la información ya extraída y estructurada por el gestor de Solicitud — no relee los doc… | W9: [M] Capa de duplicados determinística, sin componente de IA: aplica reglas de negocio por especiali… | X9: [XL] Gobernanza de reglas: en vez de traer el motor de reglas al gestor, este consume una tool que i… | AA9: [M] Se debe habilitar la opción de solicitud de requisitos (notificar al cliente); al adjuntar el s… | AB9: [M] Criterios de priorización de prestadores: quejas (Medallia), satisfacción, disponibilidad de ci… | AC9: [XL] Arranca con motor 100% determinístico (reglas duras de elegibilidad, convenios, capacidad, ubic… | AD9: [L] Pendiente definir el dueño y el mecanismo de sincronización de las reglas de direccionamiento/c… | AF9: [S] Visión ampliada: capacidades proactivas (contactar directamente al cliente/prestador) y potesta… | AG9: [XS] Notifica al asegurado ante incumplimiento de SLA (mensaje de acompañamiento) y alerta intername… | AH9: [L] Reto de integración en tiempo real con prestadores — hoy no existe (solo portal con interacción… | AI9: [S] Medir KPIs de eficiencia y productividad: tiempo de ciclo promedio, tiempo de espera, tiempo de… | AJ9: [M] La Torre de Control no tendrá un front propio de visualización al usuario final: la visibilidad… | AL9: [XL] Visión ideal (aún no lograda ni por EPS): OTP de asistencia + interoperabilidad directa con el … | AO9: [S] Objetivo: que autorización y tarifa contratada queden tan conectadas que no haya que glosar ni … | AP9: [L] El proceso de conciliación y glosas (conocido en el negocio como 'finiquito') no se considera u…
A10: Req. 5 | C10: [L] Acuerdo formal de capacidad y disponibilidad con el equipo de SuraHis para la exposición de API… | D10: [M] Principio "coreless": la lógica de negocio (reglas, políticas, convenios) se desacopla de los c… | E10: [L] Confirmar el orden de dependencia entre gestores: cada gestor requiere el evento o salida del a… | F10: [L] La Solicitud y la Autorización hacen parte del core (SuraHis), por lo que SuraHis debe garantiz… | I10: [S] Genera un ID temporal como número radicador (correlation ID), y almacena la información de form… | J10: [M] Comprobación de derechos vía API de SuraHis (no Global Web) — mayor resiliencia y flexibilidad … | K10: [M] Integralidad automática con EPS Sura cuando la póliza voluntaria no cubre el servicio y se gene… | L10: [S] Custodia temporal de historia clínica/orden médica en componente propio. | M10: [XL] Definir si el radicado debe quedar garantizado en SuraHis desde el primer release, o si basta c… | N10: [L] No hay rechazo automático: todo lo que el agente no puede resolver pasa a bandeja humana indica… | O10: [L] Validar qué tipos de archivo puede almacenar el repositorio documental de los gestores (si admi… | Q10: [M] No requiere segundo factor de autenticación en el flujo de solicitud desde la app (sí se evalua… | R10: [XL] Solicitud en el exterior: flujo distinto al general — no genera una autorización tradicional; l… | U10: [M] Niveles de escalamiento: Nivel 1 automático · Nivel 2 administrativo · Niveles 3 (enfermeras/in… | V10: [XXL] Debe consultar políticas/reglas a SuraHis manteniendo también reglas propias de agente (modelo … | W10: [M] El gestor no rellena información faltante ni garantiza la completitud de la información: entra … | X10: [L] SuraHis dispone de un módulo parametrizable de reglas duras que permite eliminarlas, modificarl… | AA10: [M] Con la negación de un servicio se debe activar la radicación automática de la solicitud de inte… | AB10: [S] Si el prestador elegido no tiene convenio vigente, se asigna automáticamente el mejor rankeado … | AC10: [L] LLM reservado solo para casos no estructurados o de explicación — no es prioridad para el arran… | AF10: [S] Responsable de detectar comportamiento anómalo de los agentes (ej. ratio de rechazos fuera de l… | AG10: [S] Requiere vista individual (línea de tiempo por solicitud) y vista grupal/masiva (operación agre… | AH10: [L] Datalake de autorizaciones como entregable técnico del Release 3 (feb-abr 2027), con apoyo del … | AI10: [S] Reportar a los líderes de operación cuando un equipo esté saturado o dejando de recibir autoriz… | AJ10: [M] Trazar el límite entre las alertas que resuelve el propio core con un timer (ej. SLA vencido) y… | AL10: [XS] Mecanismo de registro de asistencia en SuraHis. | AO10: [S] El fraude también puede materializarse aquí (sobrefacturación, sobretratamiento) — debe tratars…
A11: Req. 6 | C11: [L] Transferencia de contexto funcional al equipo técnico: proceso actual de autorizaciones, modelo… | D11: [XXL] El core (SuraHis) debe ser la fuente de la verdad transaccional, no el motor de reglas — princi… | E11: [S] Cada gestor tendría base de datos propia, independiente y desacoplada. | F11: [M] Marco de buenas prácticas para sistemas agénticos: criterios de asertividad y trazabilidad para… | I11: [XS] Lleva los documentos a P8. | J11: [L] OCR/IA: LLM multimodal interpreta documentos directamente (15-40 seg); reutiliza el agente de p… | K11: [S] Nueva funcionalidad "Reestudio": permite pedir reevaluación de una solicitud negada adjuntando … | L11: [S] Riesgo técnico abierto: Super App en Google Cloud vs. resto del ecosistema en Azure. | M11: [M] El agente receptor no asume que los archivos llegan bien identificados ni separados: debe detec… | N11: [M] Capa de auditoría: analiza el histórico de solicitudes y reporta patrones a la Torre de Control… | O11: [L] Flujo de activación confirmado: el Front informa a Siniestro Integral, este guarda la informaci… | Q11: [M] Front con/sin documentos dependiendo del tipo de servicio de cara al prestador; front con docum… | R11: [M] Caso especial de inclusión de recién nacido para atención urgente: flujo corto e independiente,… | U11: [L] El agente entrega un "concepto"/resumen de su análisis al escalar a la bandeja manual, para ace… | V11: [XXL] Arquitectura híbrida multiagente propuesta: agente determinístico (coberturas/exclusiones) + ag… | W11: [L] Si durante la evaluación falta un dato que no era obligatorio en la solicitud pero sí es necesa… | X11: [M] El Gestor de Evaluación no es transversal: está diseñado específicamente para autorizaciones de… | AA11: [S] Se debe habilitar la opción de resignación manual de solicitudes a otro evaluador (novedades co… | AB11: [L] Si no hay red contratada en la ciudad, se recomienda la ciudad más cercana o se escala a Conven… | AC11: [M] Niveles de madurez agéntica: Nivel 1 determinístico → Nivel 2 + asistente explicativo → Nivel 3… | AF11: [M] Expone información distinta según el actor consultante (prestador, cliente, asesor), enmascaran… | AG11: [M] La Torre de Control no emite los eventos de cambio de estado (los emite el componente dueño de … | AH11: [XL] Concepto en discusión: 'agente auditor' transversal que retroalimente a los gestores con aprend… | AI11: [S] Detectar cuentas por pagar próximas a vencer y generar alertas, evitando llamadas de prestadore… | AJ11: [L] Nuevas entidades que deben emitir eventos hacia la Torre de Control: cuenta médica, orden de pa… | AL11: [XXL] El gestor de Prestación no se implementa como componente agéntico independiente para el alcance… | AO11: [M] Se propone reutilizar el agente ya existente en EPS que lee/transcribe autorizaciones y valida …
A14: Leyenda de release | D14: RESULTADO
A15: Sprint 0 | D15: Tablero | F15: Azure DevOps
A16: Release 1 | D16: ID de la iniciativa en Azure | F16: PENDIENTE POR CONFIRMAR
A17: Release 2 | D17: URL de la iniciativa en Azure | F17: PENDIENTE POR CONFIRMAR
A18: Release 3 | D18: Total de requisitos mapeados | F18: =COUNTA(Estimación!A6:A243) -> 173
A19: Fase posterior | D19: Actividades en Sprint 0 | F19: =COUNTIF(Estimación!D6:D243,"Sprint 0") -> 11
D20: Requisitos en Release 1 (MVP dic-2026) | F20: =COUNTIF(Estimación!D6:D243,"Release 1") -> 13
D21: Requisitos en Release 2 | F21: =COUNTIF(Estimación!D6:D243,"Release 2") -> 78
D22: Requisitos en Release 3 | F22: =COUNTIF(Estimación!D6:D243,"Release 3") -> 52
D23: Requisitos talla XL/XXL | F23: =COUNTIF(Estimación!H6:H243,"XL")+COUNTIF(Estimación!H6:H243,"XXL") -> 26
D24: Total días hábiles estimados | F24: =SUM(Estimación!I6:I243) -> 1442

Sheet Estimación
A1: BACKLOG DE ESTIMACIÓN — requisitos funcionales y no funcionales con fecha
A2: Sprints de 11 días hábiles, calendario de Colombia (festivos incluidos). Fecha inicio/fin calculada según la talla de cada requisito y el carril del squad que lo atiende (ver hoja 'Equipos y Paralelización'). La talla es una heurística de primera pasada — Estado de refinamiento indica que debe confirmarse en el taller de estimación.
A5: ID | B5: Gestor / Frente | C5: Equipo | D5: Release | E5: Actividad / Requisito | F5: Entregable | G5: Prioridad | H5: Talla | I5: Duración (días hábiles) | J5: Sprint(s) | K5: Fecha inicio | L5: Fecha fin | M5: Dependencia | N5: Seguimiento | O5: Estado de refinamiento
A6: REQ-179 | B6: Canales / Front Externos | C6: Canales | D6: Sprint 0 | E6: Confirmación del alcance del Release 1 con negocio y con el equipo de canales: rol y canal específicos, y compatibilidad de cronogramas. | G6: Debe tener | H6: M | I6: 5 | J6: Sprint 0 | K6: 46266 | L6: 46272 | M6: James no había entregado su estimación de esfuerzo al 18-ago. | N6: — | O6: Por confirmar talla
A7: REQ-170 | B7: Transversal / Principios generales | C7: Plataforma | D7: Sprint 0 | E7: Conformación y onboarding del equipo: definición de squads, roles y dedicaciones, y capacitación del personal nuevo en el dominio de autorizaciones de salud. | G7: Debe tener | H7: M | I7: 5 | J7: Sprint 0 | K7: 46266 | L7: 46272 | M7: Armar y capacitar un equipo nuevo puede tomar más de la mitad de septiembre. | N7: Riesgo señalado en la sesión del 18-ago | O7: Por confirmar talla
A8: REQ-171 | B8: Transversal / Principios generales | C8: Plataforma | D8: Sprint 0 | E8: Habilitación de ambientes de desarrollo y pruebas, infraestructura base, repositorios, pipelines de CI/CD y estándares de código. | G8: Debe tener | H8: M | I8: 5 | J8: Sprint 0 | K8: 46266 | L8: 46272 | M8: — | N8: — | O8: Por confirmar talla
A9: REQ-172 | B9: Transversal / Principios generales | C9: Plataforma | D9: Sprint 0 | E9: Configuración del Runtime agéntico y del Control Plane corporativo (gateway de consumo de LLM y gestión de prompts) para el equipo de Gestores. | G9: Debe tener | H9: L | I9: 10 | J9: Sprint 0 | K9: 46266 | L9: 46279 | M9: Depende del avance de la plataforma agéntica corporativa que construye el equipo de IA. | N9: — | O9: Por confirmar talla
A10: REQ-173 | B10: Transversal / Principios generales | C10: Plataforma | D10: Sprint 0 | E10: Elaboración del borrador del catálogo de eventos y de los contratos de API que servirán de base al Release 1. | G10: Debe tener | H10: L | I10: 10 | J10: Sprint 0 | K10: 46266 | L10: 46279 | M10: — | N10: Camino crítico: sin este contrato ningún squad puede construir | O10: Por confirmar talla
A11: REQ-174 | B11: Transversal / Principios generales | C11: Plataforma | D11: Sprint 0 | E11: Acuerdo formal de capacidad y disponibilidad con el equipo de SuraHis para la exposición de APIs y eventos del core. | G11: Debe tener | H11: L | I11: 10 | J11: Sprint 0 | K11: 46273 | L11: 46286 | M11: Dependencia crítica número uno del proyecto. | N11: Requiere compromiso explícito con Andrés Charry | O11: Por confirmar talla
A12: REQ-175 | B12: Transversal / Principios generales | C12: Plataforma | D12: Sprint 0 | E12: Transferencia de contexto funcional al equipo técnico: proceso actual de autorizaciones, modelo de estados, entidades y decisiones de arquitectura ya tomadas. | G12: Debe tener | H12: L | I12: 10 | J12: Sprint 0 | K12: 46273 | L12: 46286 | M12: — | N12: — | O12: Por confirmar talla
A13: REQ-176 | B13: Transversal / Principios generales | C13: Plataforma | D13: Sprint 0 | E13: Cierre del ejercicio de dimensionamiento de agentes y estimación de costo, aplicando el driver construido con NTT Data. | G13: Debe tener | H13: M | I13: 5 | J13: Sprint 0 | K13: 46280 | L13: 46286 | M13: El driver estaba en borrador al 20-ago. | N13: Ejercicio iniciado el 21-ago de 1:30 p.m. a 5:00 p.m. | O13: Por confirmar talla
A14: REQ-178 | B14: Transversal / Principios generales | C14: Plataforma | D14: Sprint 0 | E14: Definición del umbral de asertividad y de las métricas de calidad de los agentes que se aplicarán desde el Release 1. | G14: Debe tener | H14: M | I14: 5 | J14: Sprint 0 | K14: 46280 | L14: 46286 | M14: Valor exacto del umbral por definir. | N14: — | O14: Por confirmar talla
A15: REQ-180 | B15: Transversal / Principios generales | C15: Plataforma | D15: Sprint 0 | E15: Validación con el equipo técnico de los tallajes y estimaciones preliminares, y ajuste del backlog del Release 1 antes de iniciar la implementación. | G15: Debe tener | H15: M | I15: 5 | J15: Sprint 0 | K15: 46287 | L15: 46293 | M15: — | N15: — | O15: Por confirmar talla
A16: REQ-177 | B16: Gestor de Solicitud | C16: Solicitud | D16: Sprint 0 | E16: Decisión técnica del lector de IA a reutilizar (ADR vs. desarrollo de TT) y prueba de concepto de la extracción documental sobre documentos reales. | G16: Debe tener | H16: L | I16: 10 | J16: Sprint 0 | K16: 46266 | L16: 46279 | M16: Impactada por el recorte de presupuesto del equipo de salud modular. | N16: — | O16: Por confirmar talla
A17: REQ-076 | B17: Transversal / Principios generales | C17: Plataforma | D17: Release 1 | E17: Arquitectura de microservicios, agéntica, dirigida por eventos (EDA), moderna y desacoplada — se acopla a los cores existentes, no los reemplaza. | F17: Arquitectura | G17: Debe tener | H17: XL | I17: 20 | J17: S1–S2 | K17: 46296 | L17: 46324 | M17: — | N17: — | O17: Talla confirmada
A18: REQ-079 | B18: Transversal / Principios generales | C18: Plataforma | D18: Release 1 | E18: Demanda cruzada Cores para emisión de Eventos (Sura His, Siniestro Integral) | F18: Desarrollo de implementaciones en Cores de cara a los eventos | G18: Debe tener | H18: L | I18: 10 | J18: S1 | K18: 46303 | L18: 46310 | M18: Equipos Core para las demandas cruzadas | N18: — | O18: Talla confirmada
A19: REQ-082 | B19: Transversal / Principios generales | C19: Plataforma | D19: Release 1 | E19: Ajustes Siniestro Integral para que sea el canal unificado de Registro y seguimiento de solicitudes | F19: Desarrollo de implementación en siniestro integral | G19: Debe tener | H19: L | I19: 10 | J19: S2–S3 | K19: 46325 | L19: 46332 | M19: — | N19: — | O19: Talla confirmada
A20: REQ-009 | B20: Siniestro Integral | C20: Solicitud | D20: Release 1 | E20: Modelo de datos "padre-hijo": la solicitud es el padre; cada autorización por servicio/CUPS es un hijo con estado propio. | G20: Debe tener | H20: M | I20: 5 | J20: S1 | K20: 46296 | L20: 46302 | M20: — | N20: — | O20: Talla confirmada
A21: REQ-010 | B21: Gestor de Solicitud | C21: Solicitud | D21: Release 1 | E21: Recoger definiciones, lineamientos que tengamos en compañía y habilitadores que podamos reutilizar en la arquitectura. | F21: Lineamientos y habilitadores para la construcción del Gestor | G21: Debe tener | H21: L | I21: 10 | J21: S1 | K21: 46296 | L21: 46310 | M21: — | N21: — | O21: Talla confirmada
A22: REQ-011 | B22: Siniestro Integral | C22: Solicitud | D22: Release 1 | E22: Genera un ID temporal como número radicador (correlation ID), y almacena la información de forma temporal. | G22: Debe tener | H22: S | I22: 3 | J22: S1 | K22: 46296 | L22: 46300 | M22: — | N22: — | O22: Talla confirmada
A23: REQ-012 | B23: Siniestro Integral | C23: Solicitud | D23: Release 1 | E23: Lleva los documentos a P8. | G23: Debe tener | H23: XS | I23: 1 | J23: S1 | K23: 46296 | L23: 46296 | M23: — | N23: — | O23: Talla confirmada
A24: REQ-013 | B24: Siniestro Integral | C24: Solicitud | D24: Release 1 | E24: Publica el evento que activa al core de salud (SuraHis) para la generación de la solicitud; ese mismo evento alimenta el flujo de solicitud/autorización para la Torre de Control. | G24: Debe tener | H24: M | I24: 5 | J24: S1 | K24: 46297 | L24: 46303 | M24: — | N24: — | O24: Talla confirmada
A25: REQ-017 | B25: Gestor de Solicitud | C25: Solicitud | D25: Release 1 | E25: Habilitar plataforma necesaria por el Gestor solicitud | F25: Habilitar Tenant/Dominio capacidades para los agentes del Gestor de Solicitud(Plataforma agéntica) | G25: Debe tener | H25: XL | I25: 20 | J25: S1–S3 | K25: 46301 | L25: 46345 | M25: — | N25: — | O25: Talla confirmada
A26: REQ-065 | B26: Gestor de Solicitud | C26: Solicitud | D26: Release 1 | E26: Implementar el Gestor Solicitud (Agentes y herramientas) | F26: Agente implementado en el Gestor de Solicitud | G26: Debe tener | H26: L | I26: 10 | J26: S1–S2 | K26: 46303 | L26: 46317 | O26: Talla confirmada
A27: REQ-084 | B27: Gestor de Solicitud | C27: Solicitud | D27: Release 1 | E27: Despliegue del Agente en los diferentes ambientes | F27: Agente desplegado en el Gestor de Solicitud | G27: Debe tener | H27: M | I27: 5 | J27: S1 | K27: 46303 | L27: 46310 | M27: — | N27: — | O27: Talla confirmada
A28: REQ-086 | B28: Gestor de Solicitud | C28: Solicitud | D28: Release 1 | E28: Liberación agente | F28: Gestor productivo para el canal, operación y rol definidos | G28: Debe tener | H28: M | I28: 5 | J28: S1 | K28: 46304 | L28: 46311 | M28: — | N28: — | O28: Talla confirmada
A29: REQ-087 | B29: Gestor de Solicitud | C29: Solicitud | D29: Release 1 | E29: Entendimiento del proceso de Evaluación y sus requerimientos | F29: Información fundamental para la evaluación (Mínimos requeridos) | G29: Debe tener | H29: L | I29: 10 | J29: S1–S2 | K29: 46311 | L29: 46324 | M29: — | N29: — | O29: Talla confirmada
A30: REQ-001 | B30: Canales / Front Externos | C30: Canales | D30: Release 2 | E30: Comprobación de derechos (vigencia de póliza, mora) obligatoria al inicio del flujo, antes de pedir cualquier otro dato (se hace directamente desde el front). | G30: Debe tener | H30: M | I30: 5 | J30: S7 | K30: 46399 | L30: 46405 | M30: — | N30: — | O30: Por confirmar talla
A31: REQ-002 | B31: Canales / Front Externos | C31: Canales | D31: Release 2 | E31: Documentos aparentemente inválidos no permiten continuar con la creación de la solicitud (agente IA light). | G31: Debe tener | H31: L | I31: 10 | J31: S7 | K31: 46399 | L31: 46412 | M31: — | N31: — | O31: Por confirmar talla
A32: REQ-003 | B32: Canales / Front Externos | C32: Canales | D32: Release 2 | E32: Omnicanalidad real: el historial de solicitudes/autorizaciones debe verse igual sin importar el canal de origen. | G32: Debe tener | H32: S | I32: 3 | J32: S7 | K32: 46399 | L32: 46401 | M32: — | N32: — | O32: Por confirmar talla
A33: REQ-004 | B33: Canales / Front Externos | C33: Canales | D33: Release 2 | E33: No requiere segundo factor de autenticación en el flujo de solicitud desde la app (sí se evaluará para reembolsos, por implicar pago directo). | G33: Debe tener | H33: M | I33: 5 | J33: S7 | K33: 46402 | L33: 46408 | M33: — | N33: — | O33: Por confirmar talla
A34: REQ-005 | B34: Canales / Front Externos | C34: Canales | D34: Release 2 | E34: Front con/sin documentos dependiendo del tipo de servicio de cara al prestador; front con documentos de cara al asesor y al cliente. | G34: Debe tener | H34: M | I34: 5 | J34: S7 | K34: 46406 | L34: 46412 | M34: — | N34: — | O34: Por confirmar talla
A35: REQ-066 | B35: Gestor de Solicitud (Canales) | C35: Canales | D35: Release 2 | E35: Selección de prestador: el campo queda como opcional y se traslada a un paso posterior del flujo (después del OCR de los documentos adjuntos), donde ya se puede sugerir un prestador con datos precargados. | G35: Debe tener | H35: S | I35: 3 | J35: S7 | K35: 46409 | L35: 46413 | M35: — | N35: Acordado con equipo de Canales/UX (James, Andrea, Carlos) | O35: Por confirmar talla
A36: REQ-067 | B36: Gestor de Solicitud (Canales) | C36: Canales | D36: Release 2 | E36: Reestudio: aplica solo cuando la autorización fue negada y el asegurado no está de acuerdo; el sistema explica el motivo, el usuario adjunta nuevos documentos con motivo en texto libre, y la reevaluación la hace el mismo evaluador que negó el caso. Se diferencia de 'documentos pendientes', que ocurre durante la evaluación por falta de soportes. | G36: Debe tener | H36: M | I36: 5 | J36: S7–S8 | K36: 46413 | L36: 46419 | M36: — | N36: — | O36: Por confirmar talla
A37: REQ-068 | B37: Gestor de Solicitud (Canales) | C37: Canales | D37: Release 2 | E37: Notificación y visibilidad cruzada cliente-prestador: se notifica al cliente cuando un prestador radica una solicitud a su nombre; el cliente debe poder ver todo lo relacionado con su caso sin importar el canal de radicación, para evitar solicitudes duplicadas. | G37: Debe tener | H37: M | I37: 5 | J37: S7–S8 | K37: 46413 | L37: 46419 | M37: — | N37: — | O37: Por confirmar talla
A38: REQ-069 | B38: Gestor de Solicitud (Canales) | C38: Canales | D38: Release 2 | E38: Anulación de solicitudes: solo la puede hacer el prestador, y solo si el estado es 'en proceso'. El estado 'anulada' y su motivo deben ser visibles para el asegurado en lenguaje claro, incluyendo el caso de una autorización ya aprobada que se anula después. | G38: Debe tener | H38: S | I38: 3 | J38: S8 | K38: 46414 | L38: 46416 | M38: — | N38: — | O38: Por confirmar talla
A39: REQ-070 | B39: Gestor de Solicitud (Canales) | C39: Canales | D39: Release 2 | E39: Solicitud en el exterior: flujo distinto al general — no genera una autorización tradicional; llega a una bandeja de gestión que tramita con un proveedor externo y responde al asegurado por correo. | G39: Debe tener | H39: XL | I39: 20 | J39: S8–S10 | K39: 46419 | L39: 46444 | M39: Validar con el equipo de exterior si los campos/documentos pueden reutilizar el flujo general. | N39: Pendiente con Tania Saldarriaga (Negocio) | O39: Por confirmar talla
A40: REQ-071 | B40: Gestor de Solicitud (Canales) | C40: Canales | D40: Release 2 | E40: Caso especial de inclusión de recién nacido para atención urgente: flujo corto e independiente, fuera del flujo general de autorizaciones (se remite al equipo de Expedición). | G40: Debe tener | H40: M | I40: 5 | J40: S8 | K40: 46420 | L40: 46426 | M40: — | N40: — | O40: Por confirmar talla
A41: REQ-072 | B41: Gestor de Solicitud (Canales) | C41: Canales | D41: Release 2 | E41: 'Solicitar estado de cuenta' se renombra de cara al usuario (los asegurados lo conocen como 'certificado de antigüedad') y vive dentro del módulo transversal de certificados de activos digitales, sin duplicar arquitectura. | G41: Debe tener | H41: L | I41: 10 | J41: S8–S9 | K41: 46420 | L41: 46433 | M41: Nombre definitivo aún por decidir. | N41: — | O41: Por confirmar talla
... A178: REQ-117 | B178: Gestor de Prestación | C178: Prestación | D178: Fase posterior | E178: Integración con la cola de eventos de interoperabilidad de historia clínica (arquitectura 2.0) para conocer si el servicio autorizado fue efectivamente atendido, sin construir un componente tecnológico nuevo en Gestores. | G178: No debería | H178: XXL | I178: 30 | J178: S26–S28 | K178: 46710 | L178: 46752 | M178: — | N178: — | O178: Por confirmar talla
...

Sheet Equipos y Paralelización
A1: DISTRIBUCIÓN DE EQUIPOS Y ANÁLISIS DE PARALELIZACIÓN
A2: El número de requisitos, los días hábiles y la ventana real se calculan directamente desde 'Backlog-Estimación'. Cada squad aparece en una fila por release porque sus ventanas están separadas en el tiempo, pero es el mismo equipo. En el Release 1 se refuerzan los carriles (Solicitud 5, Plataforma 3) para sostener la ventana de dos meses. Propuesta de trabajo para la estimación de capacidad y costo — no refleja asignaciones acordadas.
A4: Squad | B4: Gestores que atiende | C4: Composición sugerida | D4: Carriles (paralelo) | E4: FTE aprox. | F4: N.° requisitos | G4: Días hábiles acumulados | H4: Sprint inicio | I4: Ventana real (calculada) | J4: ¿Paralelizable? | K4: Dependencia bloqueante
A5: Plataforma (Sprint 0) | B5: Transversal / Principios generales (EDA, APIs, MCP, contingencia) | C5: 1 arquitecto de solución · 1 arquitecto de datos · 2 ingenieros de plataforma | D5: 2 | E5: 3.5 | F5: 9 | G5: 65 | H5: S0 | I5: 01-Sep-26 a 28-Sep-26 | J5: Sí, con Solicitud desde S1 | K5: Sprint 0 debe haber dejado el catálogo de eventos y los contratos de API en borrador
A6: Plataforma (Release 1) | B6: Transversal / Principios generales (EDA, APIs, MCP, contingencia) | C6: 1 arquitecto de solución · 1 arquitecto de datos · 2 ingenieros de plataforma | D6: 3 | E6: 4.5 | F6: 8 | G6: 100 | H6: S1 | I6: 01-Oct-26 a 30-Nov-26 | J6: Sí, con Solicitud desde S1 | K6: Sprint 0 debe haber dejado el catálogo de eventos y los contratos de API en borrador
A7: Plataforma (Release 2) | B7: Transversal / Principios generales (EDA, APIs, MCP, contingencia) | C7: 1 arquitecto de solución · 1 arquitecto de datos · 2 ingenieros de plataforma | D7: 2 | E7: 3.5 | F7: 10 | G7: 108 | H7: S7 | I7: 12-Jan-27 a 01-Apr-27 | J7: Sí, con Solicitud desde S1 | K7: Sprint 0 debe haber dejado el catálogo de eventos y los contratos de API en borrador
A8: Solicitud (Sprint 0) | B8: Gestor de Solicitud · Siniestro Integral | C8: 1 tech lead · 3 desarrolladores backend · 1 desarrollador Flutter | D8: 4 | E8: 6 | F8: 1 | G8: 10 | H8: S0 | I8: 01-Sep-26 a 14-Sep-26 | J8: Sí, con Plataforma desde S1 | K8: Requiere ambientes, equipo capacitado y lector de IA seleccionado en Sprint 0
A9: Solicitud (Release 1) | B9: Gestor de Solicitud · Siniestro Integral | C9: 1 tech lead · 3 desarrolladores backend · 1 desarrollador Flutter | D9: 5 | E9: 7 | F9: 12 | G9: 109 | H9: S1 | I9: 01-Oct-26 a 19-Nov-26 | J9: Sí, con Plataforma desde S1 | K9: Requiere ambientes, equipo capacitado y lector de IA seleccionado en Sprint 0
A10: Solicitud (Release 2) | B10: Gestor de Solicitud · Siniestro Integral | C10: 1 tech lead · 3 desarrolladores backend · 1 desarrollador Flutter | D10: 4 | E10: 6 | F10: 29 | G10: 227 | H10: S7 | I10: 12-Jan-27 a 09-Apr-27 | J10: Sí, con Plataforma desde S1 | K10: Requiere ambientes, equipo capacitado y lector de IA seleccionado en Sprint 0
A11: Canales (Sprint 0) | B11: Canales / Front Externos · Gestor de Solicitud (Canales) | C11: 1 UX/UI · 3 desarrolladores front (Flutter/web) | D11: 3 | E11: 5 | F11: 1 | G11: 5 | H11: S0 | I11: 01-Sep-26 a 07-Sep-26 | J11: Sí, desde el Release 2 | K11: En Release 1 se reutilizan los canales existentes; depende de la estimación de esfuerzo de James
A12: Canales (Release 2) | B12: Canales / Front Externos · Gestor de Solicitud (Canales) | C12: 1 UX/UI · 3 desarrolladores front (Flutter/web) | D12: 3 | E12: 5 | F12: 13 | G12: 84 | H12: S7 | I12: 12-Jan-27 a 26-Feb-27 | J12: Sí, desde el Release 2 | K12: En Release 1 se reutilizan los canales existentes; depende de la estimación de esfuerzo de James
A13: Evaluación | B13: Gestor de Evaluación | C13: 1 tech lead · 2 desarrolladores backend · 1 ingeniero de IA | D13: 3 | E13: 4.5 | F13: 26 | G13: 283 | H13: S7 | I13: 12-Jan-27 a 08-Jun-27 | J13: Sí, en paralelo con Canales en Release 2 | K13: Su mínimo viable se estimó en ~4 meses; requiere el modelo de datos y eventos del Release 1 estables
